Workbook

Sheet Ark1
A1: Tensar Pave
A2: Dataudtræk ERO/AKK 21/12-2016 | F2: Armering for hver 40 cm
D3: Armeret | J3: BG armeret | R3: Uarneret | W3: BG uarmeret
A4: Knust Sten - Skærver | D4: Phi > 45 grader | R4: Phi > 45 grader
B5: Eo | C5: 45 | D5: 80 | E5: 100 | F5: 120 | G5: 150 | H5: MPA | Q5: 45 | R5: 80 | S5: 100 | T5: 120 | U5: 150 | V5: MPA
A6: Eu
A7: 5 | B7: nedre | C7: 275 | D7: 385 | E7: 645 | F7: 710 | G7: 825 | Q7: 500 | R7: 630 | S7: 900 | T7: 1150 | U7: 1400
B8: øvre | C8: 275 | D8: 495 | E8: 815 | F8: 880 | G8: 975
A10: 10 | B10: nedre | C10: 275 | D10: 285 | E10: 410 | F10: 495 | G10: 630 | Q10: 500 | R10: 500 | S10: 680 | T10: 800 | U10: 1010
B11: øvre | C11: 275 | D11: 375 | E11: 545 | F11: 645 | G11: 760
A13: 15 | B13: nedre | C13: 275 | D13: 215 | E13: 305 | F13: 375 | G13: 475 | Q13: 500 | R13: 350 | S13: 490 | T13: 600 | U13: 760
B14: øvre | C14: 275 | D14: 270 | E14: 385 | F14: 475 | G14: 575
A16: 20 | B16: nedre | C16: 100 | D16: 170 | E16: 255 | F16: 300 | G16: 385 | Q16: 300 | R16: 300 | S16: 380 | T16: 480 | U16: 590
B17: øvre | C17: 100 | D17: 215 | E17: 315 | F17: 385 | G17: 460
A19: 30 | B19: nedre | C19: 100 | D19: 215 | E19: 170 | F19: 215 | G19: 280 | Q19: 300 | R19: 190 | S19: 270 | T19: 335 | U19: 430
B20: øvre | C20: 100 | D20: 260 | E20: 215 | F20: 275 | G20: 340
A22: 40 | B22: nedre | C22: 100 | D22: 100 | E22: 130 | F22: 165 | G22: 220 | Q22: 300 | R22: 140 | S22: 220 | T22: 270 | U22: 330
B23: øvre | C23: 100 | D23: 100 | E23: 165 | F23: 205 | G23: 265
A25: Sand/grus | D25: Phi > 35 grader | R25: Phi > 35 grader
B26: Eo | C26: 45 | D26: 80 | E26: 100 | F26: 120 | G26: 150 | H26: MPA | J26: 30 | K26: 45 | L26: 60 | M26: 80 | N26: 120 | O26: 150 | Q26: 45 | R26: 80 | S26: 100 | T26: 120 | U26: 150 | V26: MPA | W26: 30 | X26: 45 | Y26: 60 | Z26: 80 | AA26: 120 | AB26: 150
A27: Eu
A28: 5 | B28: nedre | C28: 275 | D28: 495 | E28: 815 | F28: 880 | G28: 975 | J28: 600 | K28: 680 | L28: 800 | M28: 900 | N28: 950 | O28: 1000 | Q28: 500 | R28: 820 | S28: 1200 | T28: 1430 | U28: 1750 | W28: 900 | X28: 1000 | Y28: 1110 | Z28: 1200 | AA28: 1300 | AB28: 1400
B29: øvre | C29: 275 | D29: 605 | E29: 1065 | F29: 1085 | G29: 1295
A31: 10 | B31: nedre | C31: 275 | D31: 375 | E31: 545 | F31: 645 | G31: 760 | J31: 350 | K31: 480 | L31: 560 | M31: 600 | N31: 700 | O31: 770 | Q31: 500 | R31: 620 | S31: 880 | T31: 1050 | U31: 1300 | W31: 600 | X31: 700 | Y31: 800 | Z31: 900 | AA31: 1000 | AB31: 1100
B32: øvre | C32: 275 | D32: 455 | E32: 755 | F32: 790 | G32: 1005
A34: 15 | B34: nedre | C34: 275 | D34: 270 | E34: 385 | F34: 475 | G34: 575 | J34: 200 | K34: 320 | L34: 400 | M34: 480 | N34: 580 | O34: 650 | Q34: 500 | R34: 460 | S34: 620 | T34: 760 | U34: 920 | W34: 400 | X34: 500 | Y34: 600 | Z34: 700 | AA34: 800 | AB34: 900
B35: øvre | C35: 275 | D35: 335 | E35: 535 | F35: 575 | G35: 765
A37: 20 | B37: nedre | C37: 100 | D37: 215 | E37: 315 | F37: 385 | G37: 460 | J37: 200 | K37: 200 | L37: 300 | M37: 240 | N37: 480 | O37: 560 | Q37: 300 | R37: 350 | S37: 470 | T37: 590 | U37: 710 | W37: 250 | X37: 375 | Y37: 500 | Z37: 600 | AA37: 680 | AB37: 780
B38: øvre | C38: 135 | D38: 260 | E38: 400 | F38: 465 | G38: 620
A40: 30 | B40: nedre | C40: 100 | D40: 145 | E40: 215 | F40: 275 | G40: 340 | K40: 200 | L40: 200 | M40: 200 | N40: 330 | O40: 500 | Q40: 300 | R40: 235 | S40: 335 | T40: 420 | U40: 510 | W40: 0 | X40: 200 | Y40: 300 | Z40: 400 | AA40: 490 | AB40: 580
B41: øvre | C41: 100 | D41: 175 | E41: 295 | F41: 330 | G41: 450
A43: 40 | B43: nedre | C43: 100 | D43: 100 | E43: 165 | F43: 205 | G43: 265 | N43: 200 | O43: 420 | Q43: 300 | R43: 140 | S43: 260 | T43: 320 | U43: 390 | X43: 50 | Y43: 150 | Z43: 250 | AA43: 360 | AB43: 460
B44: øvre | C44: 100 | D44: 115 | E44: 225 | F44: 250 | G44: 345

Sheet BG-DATA NY
A1: Byggros Designmanual
A2: Rådata AKK 21/12-2016 | H2: Armering for hver 40 cm
F3: Armeret | P3: Uarneret
A4: Knust Sten - Skærver | F4: Phi > 45 grader | P4: Phi > 45 grader
B5: Eo | C5: 30 | D5: 45 | E5: 60 | F5: 80 | G5: 100 | H5: 120 | I5: 150 | J5: MPA | N5: 45 | P5: 80 | Q5: 100 | R5: 120 | S5: 150 | T5: MPA
A6: Eu
A7: 2 | B7: nedre | N7: 500 | P7: 630 | Q7: 900 | R7: 1150 | S7: 1400
B8: øvre
A10: 5 | B10: nedre | D10: 275 | F10: 385 | G10: 645 | H10: 710 | I10: 825 | N10: 500 | P10: 630 | Q10: 900 | R10: 1150 | S10: 1400
B11: øvre | D11: 275 | F11: 495 | G11: 815 | H11: 880 | I11: 975
A13: 10 | B13: nedre | D13: 275 | F13: 285 | G13: 410 | H13: 495 | I13: 630 | N13: 500 | P13: 500 | Q13: 680 | R13: 800 | S13: 1010
B14: øvre | D14: 275 | F14: 375 | G14: 545 | H14: 645 | I14: 760
A16: 15 | B16: nedre | D16: 275 | F16: 215 | G16: 305 | H16: 375 | I16: 475 | N16: 500 | P16: 350 | Q16: 490 | R16: 600 | S16: 760
B17: øvre | D17: 275 | F17: 270 | G17: 385 | H17: 475 | I17: 575
A19: 20 | B19: nedre | D19: 100 | F19: 170 | G19: 255 | H19: 300 | I19: 385 | N19: 300 | P19: 300 | Q19: 380 | R19: 480 | S19: 590
B20: øvre | D20: 100 | F20: 215 | G20: 315 | H20: 385 | I20: 460
A22: 30 | B22: nedre | D22: 100 | F22: 215 | G22: 170 | H22: 215 | I22: 280 | N22: 300 | P22: 190 | Q22: 270 | R22: 335 | S22: 430
B23: øvre | D23: 100 | F23: 260 | G23: 215 | H23: 275 | I23: 340
A25: 40 | B25: nedre | D25: 100 | F25: 100 | G25: 130 | H25: 165 | I25: 220 | N25: 300 | P25: 140 | Q25: 220 | R25: 270 | S25: 330
B26: øvre | D26: 100 | F26: 100 | G26: 165 | H26: 205 | I26: 265
A27: Opslagsdiagram - bæreevne Eu i forhold til bæreevne på top af bærelag Eo
F28: Armeret | P28: Uarneret
A29: Sand/grus | F29: Phi > 35 grader | P29: Phi > 35 grader
B30: Eo | C30: 30 | D30: 45 | E30: 60 | F30: 80 | G30: 100 | H30: 120 | I30: 150 | J30: MPA | M30: 30 | N30: 45 | O30: 60 | P30: 80 | Q30: 100 | R30: 120 | S30: 150 | T30: MPA
A31: Eu
A32: 2 | B32: nedre | C32: 600 | D32: 650 | E32: 700 | F32: 800 | G32: 900 | H32: 1050 | I32: 1200 | M32: 900 | N32: 1000 | O32: 1100 | P32: 1200 | Q32: 1350 | R32: 1500 | S32: 1700
M33: =+M32*0.65 -> 585 | N33: =+N32*0.65 -> 650 | O33: =+O32*0.65 -> 715 | P33: =+P32*0.65 -> 780 | Q33: =+Q32*0.65 -> 877.5 | R33: =+R32*0.7 -> 1050 | S33: =+S32*0.7 -> 1190 | T33: Reduktionsværdi armeret ca.
A35: 5 | B35: nedre | C35: 450 | D35: 540 | E35: 600 | F35: 700 | G35: 800 | H35: 900 | I35: 1000 | M35: 700 | N35: 820 | O35: 950 | P35: 1100 | Q35: 1200 | R35: 1300 | S35: 1400
M36: =+M35*0.65 -> 455 | N36: =+N35*0.65 -> 533 | O36: =+O35*0.65 -> 617.5 | P36: =+P35*0.65 -> 715 | Q36: =+Q35*0.65 -> 780 | R36: =+R35*0.7 -> 910 | S36: =+S35*0.7 -> 980 | T36: Reduktionsværdi armeret ca.
A38: 10 | B38: nedre | C38: 320 | D38: 400 | E38: 450 | F38: 500 | G38: 600 | H38: 700 | I38: 770 | M38: 550 | N38: 600 | O38: 650 | P38: 800 | Q38: 900 | R38: 1000 | S38: 1100
M39: =+M38*0.65 -> 357.5 | N39: =+N38*0.65 -> 390 | O39: =+O38*0.7 -> 455 | P39: =+P38*0.7 -> 560 | Q39: =+Q38*0.7 -> 630 | R39: =+R38*0.7 -> 700 | S39: =+S38*0.7 -> 770 | T39: Reduktionsværdi armeret ca.
A41: 15 | B41: nedre | C41: 250 | D41: 330 | E41: 400 | F41: 450 | G41: 500 | H41: 580 | I41: 650 | M41: 380 | N41: 450 | O41: 500 | P41: 600 | Q41: 700 | R41: 800 | S41: 900
M42: =+M41*0.65 -> 247 | N42: =+N41*0.65 -> 292.5 | O42: =+O41*0.7 -> 350 | P42: =+P41*0.7 -> 420 | Q42: =+Q41*0.7 -> 490 | R42: =+R41*0.7 -> 560 | S42: =+S41*0.7 -> 630 | T42: Reduktionsværdi armeret ca.
A44: 20 | B44: nedre | C44: 200 | D44: 250 | E44: 280 | F44: 340 | G44: 410 | H44: 440 | I44: 530 | M44: 290 | N44: 350 | O44: 380 | P44: 480 | Q44: 580 | R44: 630 | S44: 750
M45: =+M44*0.7 -> 203 | N45: =+N44*0.7 -> 245 | O45: =+O44*0.7 -> 266 | P45: =+P44*0.7 -> 336 | Q45: =+Q44*0.7 -> 406 | R45: =+R44*0.7 -> 441 | S45: =+S44*0.7 -> 525 | T45: Reduktionsværdi armeret ca.
A47: 30 | B47: nedre | D47: 230 | E47: 270 | F47: 300 | G47: 330 | H47: 380 | I47: 420 | N47: 325 | O47: 375 | P47: 425 | Q47: 475 | R47: 550 | S47: 600
M48: =+M47*0.7 -> 0 | N48: =+N47*0.7 -> 227.5 | O48: =+O47*0.7 -> 262.5 | P48: =+P47*0.7 -> 297.5 | Q48: =+Q47*0.7 -> 332.5 | R48: =+R47*0.7 -> 385 | S48: =+S47*0.7 -> 420 | T48: Reduktionsværdi armeret ca.
A50: 40 | B50: nedre | D50: 200 | E50: 245 | F50: 280 | G50: 310 | H50: 350 | I50: 380 | N50: 250 | O50: 350 | P50: 400 | Q50: 450 | R50: 500 | S50: 550
M51: =+M50*0.7 -> 0 | N51: =+N50*0.7 -> 175 | O51: =+O50*0.7 -> 245 | P51: =+P50*0.7 -> 280 | Q51: =+Q50*0.7 -> 315 | R51: =+R50*0.7 -> 350 | S51: =+S50*0.7 -> 385 | T51: Reduktionsværdi armeret ca.
A53: Variabler/regneregler
...

Sheet Diagrammer
A1: Diagrammer — Sand/grus med φ > 35°
A3: Eu (MN/m²) | B3: Armeret Eo=30 | C3: Armeret Eo=45 | D3: Armeret Eo=60 | E3: Armeret Eo=80 | F3: Armeret Eo=100 | G3: Armeret Eo=120 | H3: Armeret Eo=150 | J3: Uarmeret Eo=30 | K3: Uarmeret Eo=45 | L3: Uarmeret Eo=60 | M3: Uarmeret Eo=80 | N3: Uarmeret Eo=100 | O3: Uarmeret Eo=120 | P3: Uarmeret Eo=150
A4: 2 | B4: =IF(ISBLANK('BG-DATA NY'!C32),NA(),'BG-DATA NY'!C32/10) -> 60 | C4: =IF(ISBLANK('BG-DATA NY'!D32),NA(),'BG-DATA NY'!D32/10) -> 65 | D4: =IF(ISBLANK('BG-DATA NY'!E32),NA(),'BG-DATA NY'!E32/10) -> 70 | E4: =IF(ISBLANK('BG-DATA NY'!F32),NA(),'BG-DATA NY'!F32/10) -> 80 | F4: =IF(ISBLANK('BG-DATA NY'!G32),NA(),'BG-DATA NY'!G32/10) -> 90 | G4: =IF(ISBLANK('BG-DATA NY'!H32),NA(),'BG-DATA NY'!H32/10) -> 105 | H4: =IF(ISBLANK('BG-DATA NY'!I32),NA(),'BG-DATA NY'!I32/10) -> 120 | J4: =IF(ISBLANK('BG-DATA NY'!M32),NA(),'BG-DATA NY'!M32/10) -> 90 | K4: =IF(ISBLANK('BG-DATA NY'!N32),NA(),'BG-DATA NY'!N32/10) -> 100 | L4: =IF(ISBLANK('BG-DATA NY'!O32),NA(),'BG-DATA NY'!O32/10) -> 110 | M4: =IF(ISBLANK('BG-DATA NY'!P32),NA(),'BG-DATA NY'!P32/10) -> 120 | N4: =IF(ISBLANK('BG-DATA NY'!Q32),NA(),'BG-DATA NY'!Q32/10) -> 135 | O4: =IF(ISBLANK('BG-DATA NY'!R32),NA(),'BG-DATA NY'!R32/10) -> 150 | P4: =IF(ISBLANK('BG-DATA NY'!S32),NA(),'BG-DATA NY'!S32/10) -> 170
A5: 5 | B5: =IF(ISBLANK('BG-DATA NY'!C35),NA(),'BG-DATA NY'!C35/10) -> 45 | C5: =IF(ISBLANK('BG-DATA NY'!D35),NA(),'BG-DATA NY'!D35/10) -> 54 | D5: =IF(ISBLANK('BG-DATA NY'!E35),NA(),'BG-DATA NY'!E35/10) -> 60 | E5: =IF(ISBLANK('BG-DATA NY'!F35),NA(),'BG-DATA NY'!F35/10) -> 70 | F5: =IF(ISBLANK('BG-DATA NY'!G35),NA(),'BG-DATA NY'!G35/10) -> 80 | G5: =IF(ISBLANK('BG-DATA NY'!H35),NA(),'BG-DATA NY'!H35/10) -> 90 | H5: =IF(ISBLANK('BG-DATA NY'!I35),NA(),'BG-DATA NY'!I35/10) -> 100 | J5: =IF(ISBLANK('BG-DATA NY'!M35),NA(),'BG-DATA NY'!M35/10) -> 70 | K5: =IF(ISBLANK('BG-DATA NY'!N35),NA(),'BG-DATA NY'!N35/10) -> 82 | L5: =IF(ISBLANK('BG-DATA NY'!O35),NA(),'BG-DATA NY'!O35/10) -> 95 | M5: =IF(ISBLANK('BG-DATA NY'!P35),NA(),'BG-DATA NY'!P35/10) -> 110 | N5: =IF(ISBLANK('BG-DATA NY'!Q35),NA(),'BG-DATA NY'!Q35/10) -> 120 | O5: =IF(ISBLANK('BG-DATA NY'!R35),NA(),'BG-DATA NY'!R35/10) -> 130 | P5: =IF(ISBLANK('BG-DATA NY'!S35),NA(),'BG-DATA NY'!S35/10) -> 140
A6: 10 | B6: =IF(ISBLANK('BG-DATA NY'!C38),NA(),'BG-DATA NY'!C38/10) -> 32 | C6: =IF(ISBLANK('BG-DATA NY'!D38),NA(),'BG-DATA NY'!D38/10) -> 40 | D6: =IF(ISBLANK('BG-DATA NY'!E38),NA(),'BG-DATA NY'!E38/10) -> 45 | E6: =IF(ISBLANK('BG-DATA NY'!F38),NA(),'BG-DATA NY'!F38/10) -> 50 | F6: =IF(ISBLANK('BG-DATA NY'!G38),NA(),'BG-DATA NY'!G38/10) -> 60 | G6: =IF(ISBLANK('BG-DATA NY'!H38),NA(),'BG-DATA NY'!H38/10) -> 70 | H6: =IF(ISBLANK('BG-DATA NY'!I38),NA(),'BG-DATA NY'!I38/10) -> 77 | J6: =IF(ISBLANK('BG-DATA NY'!M38),NA(),'BG-DATA NY'!M38/10) -> 55 | K6: =IF(ISBLANK('BG-DATA NY'!N38),NA(),'BG-DATA NY'!N38/10) -> 60 | L6: =IF(ISBLANK('BG-DATA NY'!O38),NA(),'BG-DATA NY'!O38/10) -> 65 | M6: =IF(ISBLANK('BG-DATA NY'!P38),NA(),'BG-DATA NY'!P38/10) -> 80 | N6: =IF(ISBLANK('BG-DATA NY'!Q38),NA(),'BG-DATA NY'!Q38/10) -> 90 | O6: =IF(ISBLANK('BG-DATA NY'!R38),NA(),'BG-DATA NY'!R38/10) -> 100 | P6: =IF(ISBLANK('BG-DATA NY'!S38),NA(),'BG-DATA NY'!S38/10) -> 110
A7: 15 | B7: =IF(ISBLANK('BG-DATA NY'!C41),NA(),'BG-DATA NY'!C41/10) -> 25 | C7: =IF(ISBLANK('BG-DATA NY'!D41),NA(),'BG-DATA NY'!D41/10) -> 33 | D7: =IF(ISBLANK('BG-DATA NY'!E41),NA(),'BG-DATA NY'!E41/10) -> 40 | E7: =IF(ISBLANK('BG-DATA NY'!F41),NA(),'BG-DATA NY'!F41/10) -> 45 | F7: =IF(ISBLANK('BG-DATA NY'!G41),NA(),'BG-DATA NY'!G41/10) -> 50 | G7: =IF(ISBLANK('BG-DATA NY'!H41),NA(),'BG-DATA NY'!H41/10) -> 58 | H7: =IF(ISBLANK('BG-DATA NY'!I41),NA(),'BG-DATA NY'!I41/10) -> 65 | J7: =IF(ISBLANK('BG-DATA NY'!M41),NA(),'BG-DATA NY'!M41/10) -> 38 | K7: =IF(ISBLANK('BG-DATA NY'!N41),NA(),'BG-DATA NY'!N41/10) -> 45 | L7: =IF(ISBLANK('BG-DATA NY'!O41),NA(),'BG-DATA NY'!O41/10) -> 50 | M7: =IF(ISBLANK('BG-DATA NY'!P41),NA(),'BG-DATA NY'!P41/10) -> 60 | N7: =IF(ISBLANK('BG-DATA NY'!Q41),NA(),'BG-DATA NY'!Q41/10) -> 70 | O7: =IF(ISBLANK('BG-DATA NY'!R41),NA(),'BG-DATA NY'!R41/10) -> 80 | P7: =IF(ISBLANK('BG-DATA NY'!S41),NA(),'BG-DATA NY'!S41/10) -> 90
A8: 20 | B8: =IF(ISBLANK('BG-DATA NY'!C44),NA(),'BG-DATA NY'!C44/10) -> 20 | C8: =IF(ISBLANK('BG-DATA NY'!D44),NA(),'BG-DATA NY'!D44/10) -> 25 | D8: =IF(ISBLANK('BG-DATA NY'!E44),NA(),'BG-DATA NY'!E44/10) -> 28 | E8: =IF(ISBLANK('BG-DATA NY'!F44),NA(),'BG-DATA NY'!F44/10) -> 34 | F8: =IF(ISBLANK('BG-DATA NY'!G44),NA(),'BG-DATA NY'!G44/10) -> 41 | G8: =IF(ISBLANK('BG-DATA NY'!H44),NA(),'BG-DATA NY'!H44/10) -> 44 | H8: =IF(ISBLANK('BG-DATA NY'!I44),NA(),'BG-DATA NY'!I44/10) -> 53 | J8: =IF(ISBLANK('BG-DATA NY'!M44),NA(),'BG-DATA NY'!M44/10) -> 29 | K8: =IF(ISBLANK('BG-DATA NY'!N44),NA(),'BG-DATA NY'!N44/10) -> 35 | L8: =IF(ISBLANK('BG-DATA NY'!O44),NA(),'BG-DATA NY'!O44/10) -> 38 | M8: =IF(ISBLANK('BG-DATA NY'!P44),NA(),'BG-DATA NY'!P44/10) -> 48 | N8: =IF(ISBLANK('BG-DATA NY'!Q44),NA(),'BG-DATA NY'!Q44/10) -> 58 | O8: =IF(ISBLANK('BG-DATA NY'!R44),NA(),'BG-DATA NY'!R44/10) -> 63 | P8: =IF(ISBLANK('BG-DATA NY'!S44),NA(),'BG-DATA NY'!S44/10) -> 75
A9: 30 | B9: =IF(ISBLANK('BG-DATA NY'!C47),NA(),'BG-DATA NY'!C47/10) -> #N/A | C9: =IF(ISBLANK('BG-DATA NY'!D47),NA(),'BG-DATA NY'!D47/10) -> 23 | D9: =IF(ISBLANK('BG-DATA NY'!E47),NA(),'BG-DATA NY'!E47/10) -> 27 | E9: =IF(ISBLANK('BG-DATA NY'!F47),NA(),'BG-DATA NY'!F47/10) -> 30 | F9: =IF(ISBLANK('BG-DATA NY'!G47),NA(),'BG-DATA NY'!G47/10) -> 33 | G9: =IF(ISBLANK('BG-DATA NY'!H47),NA(),'BG-DATA NY'!H47/10) -> 38 | H9: =IF(ISBLANK('BG-DATA NY'!I47),NA(),'BG-DATA NY'!I47/10) -> 42 | J9: =IF(ISBLANK('BG-DATA NY'!M47),NA(),'BG-DATA NY'!M47/10) -> #N/A | K9: =IF(ISBLANK('BG-DATA NY'!N47),NA(),'BG-DATA NY'!N47/10) -> 32.5 | L9: =IF(ISBLANK('BG-DATA NY'!O47),NA(),'BG-DATA NY'!O47/10) -> 37.5 | M9: =IF(ISBLANK('BG-DATA NY'!P47),NA(),'BG-DATA NY'!P47/10) -> 42.5 | N9: =IF(ISBLANK('BG-DATA NY'!Q47),NA(),'BG-DATA NY'!Q47/10) -> 47.5 | O9: =IF(ISBLANK('BG-DATA NY'!R47),NA(),'BG-DATA NY'!R47/10) -> 55 | P9: =IF(ISBLANK('BG-DATA NY'!S47),NA(),'BG-DATA NY'!S47/10) -> 60
A10: 40 | B10: =IF(ISBLANK('BG-DATA NY'!C50),NA(),'BG-DATA NY'!C50/10) -> #N/A | C10: =IF(ISBLANK('BG-DATA NY'!D50),NA(),'BG-DATA NY'!D50/10) -> 20 | D10: =IF(ISBLANK('BG-DATA NY'!E50),NA(),'BG-DATA NY'!E50/10) -> 24.5 | E10: =IF(ISBLANK('BG-DATA NY'!F50),NA(),'BG-DATA NY'!F50/10) -> 28 | F10: =IF(ISBLANK('BG-DATA NY'!G50),NA(),'BG-DATA NY'!G50/10) -> 31 | G10: =IF(ISBLANK('BG-DATA NY'!H50),NA(),'BG-DATA NY'!H50/10) -> 35 | H10: =IF(ISBLANK('BG-DATA NY'!I50),NA(),'BG-DATA NY'!I50/10) -> 38 | J10: =IF(ISBLANK('BG-DATA NY'!M50),NA(),'BG-DATA NY'!M50/10) -> #N/A | K10: =IF(ISBLANK('BG-DATA NY'!N50),NA(),'BG-DATA NY'!N50/10) -> 25 | L10: =IF(ISBLANK('BG-DATA NY'!O50),NA(),'BG-DATA NY'!O50/10) -> 35 | M10: =IF(ISBLANK('BG-DATA NY'!P50),NA(),'BG-DATA NY'!P50/10) -> 40 | N10: =IF(ISBLANK('BG-DATA NY'!Q50),NA(),'BG-DATA NY'!Q50/10) -> 45 | O10: =IF(ISBLANK('BG-DATA NY'!R50),NA(),'BG-DATA NY'!R50/10) -> 50 | P10: =IF(ISBLANK('BG-DATA NY'!S50),NA(),'BG-DATA NY'!S50/10) -> 55
A110: Diagrammer fra eksisterende designmanual (Tensar)

Sheet Ark3
A26: Sand/grus | F26: Phi > 35 grader | P26: Phi > 35 grader
B27: Eo | C27: 30 | D27: 45 | E27: 60 | F27: 80 | G27: 100 | H27: 120 | I27: 150 | J27: MPA | M27: 30 | N27: 45 | O27: 60 | P27: 80 | Q27: 100 | R27: 120 | S27: 150 | T27: MPA
A28: Eu
A29: 2 | C29: 600 | D29: 650 | E29: 700 | F29: 800 | G29: 900 | H29: 1050 | I29: 1200 | M29: 900 | N29: 1000 | O29: 1100 | P29: 1200 | Q29: 1350 | R29: 1500 | S29: 1700
M30: =+M29*0.65 -> 585 | N30: =+N29*0.65 -> 650 | O30: =+O29*0.65 -> 715 | P30: =+P29*0.65 -> 780 | Q30: =+Q29*0.65 -> 877.5 | R30: =+R29*0.7 -> 1050 | S30: =+S29*0.7 -> 1190 | T30: Reduktionsværdi armeret ca.
A32: 5 | C32: 450 | D32: 540 | E32: 600 | F32: 700 | G32: 800 | H32: 900 | I32: 1000 | M32: 700 | N32: 820 | O32: 950 | P32: 1100 | Q32: 1200 | R32: 1300 | S32: 1400
M33: =+M32*0.65 -> 455 | N33: =+N32*0.65 -> 533 | O33: =+O32*0.65 -> 617.5 | P33: =+P32*0.65 -> 715 | Q33: =+Q32*0.65 -> 780 | R33: =+R32*0.7 -> 910 | S33: =+S32*0.7 -> 980 | T33: Reduktionsværdi armeret ca.
A35: 10 | C35: 320 | D35: 400 | E35: 450 | F35: 500 | G35: 600 | H35: 700 | I35: 770 | M35: 550 | N35: 600 | O35: 650 | P35: 800 | Q35: 900 | R35: 1000 | S35: 1100
M36: =+M35*0.65 -> 357.5 | N36: =+N35*0.65 -> 390 | O36: =+O35*0.7 -> 455 | P36: =+P35*0.7 -> 560 | Q36: =+Q35*0.7 -> 630 | R36: =+R35*0.7 -> 700 | S36: =+S35*0.7 -> 770 | T36: Reduktionsværdi armeret ca.
A38: 15 | C38: 250 | D38: 330 | E38: 400 | F38: 450 | G38: 500 | H38: 580 | I38: 650 | M38: 380 | N38: 450 | O38: 500 | P38: 600 | Q38: 700 | R38: 800 | S38: 900
M39: =+M38*0.65 -> 247 | N39: =+N38*0.65 -> 292.5 | O39: =+O38*0.7 -> 350 | P39: =+P38*0.7 -> 420 | Q39: =+Q38*0.7 -> 490 | R39: =+R38*0.7 -> 560 | S39: =+S38*0.7 -> 630 | T39: Reduktionsværdi armeret ca.
A41: 20 | C41: 200 | D41: 250 | E41: 280 | F41: 340 | G41: 410 | H41: 440 | I41: 530 | M41: 290 | N41: 350 | O41: 380 | P41: 480 | Q41: 580 | R41: 630 | S41: 750
M42: =+M41*0.7 -> 203 | N42: =+N41*0.7 -> 245 | O42: =+O41*0.7 -> 266 | P42: =+P41*0.7 -> 336 | Q42: =+Q41*0.7 -> 406 | R42: =+R41*0.7 -> 441 | S42: =+S41*0.7 -> 525 | T42: Reduktionsværdi armeret ca.
A44: 30 | D44: 230 | E44: 270 | F44: 300 | G44: 330 | H44: 380 | I44: 420 | N44: 325 | O44: 375 | P44: 425 | Q44: 475 | R44: 550 | S44: 600
M45: =+M44*0.7 -> 0 | N45: =+N44*0.7 -> 227.5 | O45: =+O44*0.7 -> 262.5 | P45: =+P44*0.7 -> 297.5 | Q45: =+Q44*0.7 -> 332.5 | R45: =+R44*0.7 -> 385 | S45: =+S44*0.7 -> 420 | T45: Reduktionsværdi armeret ca.
A47: 40 | D47: 200 | E47: 245 | F47: 280 | G47: 310 | H47: 350 | I47: 380 | N47: 250 | O47: 350 | P47: 400 | Q47: 450 | R47: 500 | S47: 550
M48: =+M47*0.7 -> 0 | N48: =+N47*0.7 -> 175 | O48: =+O47*0.7 -> 245 | P48: =+P47*0.7 -> 280 | Q48: =+Q47*0.7 -> 315 | R48: =+R47*0.7 -> 350 | S48: =+S47*0.7 -> 385 | T48: Reduktionsværdi armeret ca.
A54: Eksempel fra designmanual | J54: Eksempel nye data | L54: Eo 45 Mpa
B57: 1 lag armering | C57: 2 lag armering | D57: Uarmeret | J57: 1 lag armering | K57: Flere lag | L57: Uarmeret
A58: 0 | H58: 0 | I58: 200
A59: 10 | H59: 10 | I59: 230
A60: 20 | B60: 20 | D60: 36 | H60: 20 | I60: 200 | J60: 20
A61: 30 | B61: 14 | D61: 28 | H61: 30 | I61: 230 | J61: 12
A62: 40 | B62: 10 | D62: 20 | H62: 40 | I62: 250 | J62: 10 | L62: 20
A63: 50 | B63: 8 | D63: 15 | H63: 50 | I63: 330 | J63: 8 | L63: 15
A64: 60 | B64: 6 | D64: 12 | H64: 60 | I64: 400 | J64: 6 | L64: 18.5
A65: 70 | B65: 4.5 | D65: 9.5 | H65: 70 | I65: 540 | J65: 4.5 | L65: 15
A66: 80 | B66: 3 | D66: 7 | H66: 80 | I66: 650 | J66: 3 | L66: 12
A67: 90 | B67: 2 | D67: 5 | H67: 90 | J67: 2 | L67: 5
A68: 100 | B68: 1 | D68: 3 | H68: 100 | J68: 1 | L68: 2
A69: 110 | H69: 110
A70: 120 | H70: 120
A71: 130 | H71: 130
H72: 140
H73: 150
H74: 160

Sheet Forsøgsbeskrivelse
A3: Problemstilling
A5: Ved indbygnign af såvel stive geonet som geoceller opnås en betydelig bæreevnetilvækst. Efter indbygning synes det tydeligt at det anvendte friktionsmateriale har ændret egenskaber, positivt. Ved efterfølgende kontrolmålinger med Minifaldlod ses en bæreevnetilvækst, men ofte stemmer den målte værdi ikke overens med det oplevede resultat. Oplevelsen er som oftest at der opnåes en markant forøgelse i frktionsmaterialets stivhed, mens der til tider kun måles beskedne værdier for bæreevnetilvæksten. Med dette forsøg ønskes belyst hvilken indflyselse poissons forhold har på bæreevnetilvæksten, og hvorvidt målinger med statiske pladebelastningsforsøg giver mere retvisende resultater end forsøg med minifaldlod.
