Workbook

Sheet Claude Log
A1: Turn # | B1: Dato | C1: Bruger-anmodning | D1: Handling | E1: Detaljer | F1: Resultat
A2: 1 | B2: 46162 | C2: Opdater fane 3 'Sådan beregnes det' med ny lagtykkelse-mode forklaring: trin 3 udvidelse, nye trin 10-12, ny vigtig bemærkning. | D2: 1) Opdateret Trin 3 formel (B14) med mode-awareness. 2) Indsat 22 nye rækker efter Trin 9 (før Vigtige bemærkninger). 3) Bygget Trin 10 (rækker 44-51): plan-sammenligning med 4 tal-felter. 4) Bygget Trin 11 (rækker 52-62): reduktionsstrategi + lag-tabel + konklusion. 5) Bygget Trin 12 (rækker 63-65): geonet placering. 6) Tilføjet ny Vigtig bemærkning (rækker 77-78). 7) Formateret: row heights 20-100, wrap text, #305496 headers. | E2: Formler: 20 celler verificeret, ingen fejl. Trin 3 = B14, Trin 10 = B44:C50, Trin 11 = B52:E61, Trin 12 = B63:B64, ny bemærkning = B77:B78. Eksisterende trin 1-9 og Vigtige bemærkninger (nu rad 41-76) uberørte. Kolonne E tilføjet til lag-tabellen i Trin 11. | F2: Fane 3 opdateret og verificeret — alle 20 nye formelceller returnerer korrekte værdier uden fejl.
A3: 2 | B3: 46162 | C3: Fjern 'Uarmeret' som valg i Sektion E (C41) dropdown og opdater alle afhængige formler i arket | D3: Opdateret data validation, 3 kolonne-N formler, 2 Sektion I formler, og 3 fane-3 formler | E3: 1) C41 data validation: 'Uarmeret,1 lag,2 lag/flere lag' → '1 lag,2 lag/flere lag', default sat til '1 lag'. 2) N10: IF-wrapper fjernet → =IF($N$8="1 lag",1,2). 3) N20: Uarmeret-gren fjernet → ='4. Korrektionsfaktorer'!$E$7*($N$7-35). 4) N21: Uarmeret-gren fjernet → =$C$37. 5) C80: Uarmeret-gren fjernet, direkte test på '1 lag'. 6) C83: Dobbelt IF-wrapper fjernet. 7) Fane 3 B24 (Trin 5): ydre IF fjernet, direkte phi-tekst. 8) Fane 3 B28 (Trin 6): ydre IF fjernet, direkte net-korr tekst. 9) Fane 3 B42 (Trin 9): Uarmeret-gren fjernet fra IFERROR-wrapper. | F3: Alle 9 ændringer gennemført uden fejl. Ingen #VALUE!/#REF!/#NAME? fejl. C41 dropdown viser kun '1 lag' og '2 lag/flere lag'. Sektion I og fane 3 beregner korrekt med '1 lag' som aktiv valg.
A4: 3 | B4: 46165 | C4: Bruger spurgte om princippet bag snittegningerne i sektion H på '2. Dimensionering' og om de kan gøres automatiske. Bad om plan før ændringer, har egne design-inputs. | D4: Analyserede sektion H (B95:N138). Forklarede nuværende statiske opbygning og foreslog plan baseret på betinget formatering styret af eksisterende beregninger i M39:N44. | E4: Snittegninger er i dag stablede farvede celler i B95:B118 + F95:G111 (statiske). Beregninger i N40 (skala), N41-N42 (antal celler), N43-N44 (geonet-position) findes allerede men bruges ikke til tegningen. Foreslog: lagkode-formler per celle + betinget formatering for farver og geonet-border. | F4: Plan præsenteret med 4 åbne spørgsmål til brugeren (højde-skalering, lag-inklusion, geonet-visualisering, design-inputs). Afventer brugerens svar og design-inputs før implementering.
A5: 4 | B5: 46165 | C5: Bruger pegede på eksempel i fane 8 (I54:M62): simpel kassetegning med grå bærelag, brun råjord, geonet som sort streg, lag-labels og mm-mål. Ønsker to lige store stakke (armeret + uarmeret) i sektion H. | D5: Analyserede eksempel-tegningen på fane 8. Bekræftet designprincip og præsenteret 7-fase plan. | E5: Design: 2 farver (grå #BFBFBF bærelag, brun #948A54 råjord), sorte border-streger som geonet. Hver stak: snit-kolonne + mm-mål + lag-label. Lige højde, dynamisk skala = MAX(uarm,arm)/antal rækker. Genbruger eksisterende beregninger i M39:N44. | F5: Plan + 5 spørgsmål afsendt (asfalt med/uden, geonet-tekst, geonet-position, mm-opdeling, stak-højde). Afventer brugerens svar før byg.
A6: 5 | B6: 46165 | C6: Bruger besvarede 5 design-spørgsmål: snit starter top af bærelag, produktnavn på geonet-streg, fast placering (1 lag=mellem bærelag/råjord, 2 lag=som eksempel), mm opdelt pr lag + samlet i bund, stak-højde 6 rækker bærelag + 2 rækker råjord. | D6: Bekræftet endelig designspecifikation. Stillede 2 opfølgende spørgsmål: hvor i sektion I findes endelig lagopdeling for stabilgrus/bundsikring, og fordeling af 6 bærelagsrækker ved 2 lag. | E6: Endeligt design: fast 8 rækker høj (6 bærelag grå + 2 råjord brun). Venstre=uarmeret (C46). Højre=armeret (C47) med geonet-streger + produktnavn C36. Ved 1 lag: én streg mellem bærelag og råjord. Ved 2 lag: som fane 8 eksempel. | F6: Afventer brugerens svar på sektion I-reference og rækkefordeling ved 2 lag før implementering.
A7: 6 | B7: 46165 | C7: Byg automatiske snittegninger i sektion H på fane 2. Dimensionering jf. aftalt design. | D7: Rebuilt sektion H (B89:K112): to faste 8-rækkers stakke (6 bærelag grå + 2 råjord brun). Tilføjet dynamiske formler for mm-fordeling, geonet-streger via betinget formatering, labels med materialenavne. Justerede kolonnebredder C-K. Ryddede gamle hjælpefelter M39:N44. | E7: Layout: C=mm uarm, D=snit uarm, E=label uarm, H=mm arm, I=snit arm, J=label arm, K=geonet-label. Mm-formler: SUMIFS på D23:D25/F23:F25 (uarm lagtyk) og G74:G76/H74:H76 (arm lagtyk). Procent-mode: C46/C47 samlet. Geonet-streg på I100 (altid) + betinget streg på I97 ved 2 lag. Produktnavn fra C36 i K100 (altid) + K97 (ved 2 lag). Signaturforklaring B107:C110 opdateret. | F7: Verificeret i alle 4 mode-kombinationer (1lag/2lag x Procent/Lagtykkelser). Snittegningerne opdaterer korrekt. Bemærk: M39:N44 ryddet (ubrugte hjælpefelter fra gammel proportional skala).
A8: 7 | B8: 46165 | C8: Ret geonet-streger til stiplede linjer som i fane 8 eksempel; ret geonet-label placering. | D8: Skiftede geonet-streger til stiplet (Dash + Medium). Øverste streg på I97 via betinget formatering ved 2 lag-mode. Nederste streg på I100 statisk. Signaturforklaring B110 opdateret med stiplet streg. K97/K100 labels unmerget og top-aligned. | E8: Brugte enum-konstanter Excel.BorderLineStyle.dash + Excel.BorderWeight.medium (string-syntax 'Dash'+'Thick' fejlede tavst). I97 conditional format: '=$N$8="2 lag/flere lag"' → dash top border. I100 static dash top border. B110 dash top+bottom for tydelig vising i signaturforklaring. | F8: Begge stiplede streger virker; labels placeret korrekt. Brugeren godkendte placering.
A9: 8 | B9: 46165 | C9: Gør de to geonet-streger ensartede. | D9: Inverterede logikken på I97: statisk stiplet streg som standard, betinget formatering SKJULER stregen ved 1 lag (i stedet for at vise den ved 2 lag). Når begge streger nu er direkte cellefær-borders, ser de identiske ud. | E9: I97 EdgeTop: Dash + Medium + #000000 statisk. Conditional format: '=$N$8="1 lag"' → EdgeTop None. Matcher I100 statisk streg. | F9: Begge streger er nu visuelt identiske. Verificeret i 2 lag-mode.
A10: 9 | B10: 46165 | C10: Byt rundt på sektion H og I så de står i alfabetisk rækkefølge. | D10: Opdaterede 4 celler på fane 2 + 1 formel på fane 3. Reduktionsstrategi er nu Sektion H (B67); Snittegning er nu Sektion I (B89). Alle henvisninger i andre celler opdateret tilsvarende. | E10: 2. Dimensionering: B20 (sektion B-beskrivelse), D55 (formel-tekst), B67 (overskrift), B89 (overskrift). 3. Sådan beregnes det: B64 (formel-tekst). Selve celleområderne for sektionerne uberørte. | F10: Sektion H = Reduktionsstrategi (B67-B87), Sektion I = Snittegning (B89-K112). Henvisninger konsistente på tværs af bogen.
A11: 10 | B11: 46165 | C11: Opdater C105 (bærelagstykkelse uarmeret) så den også tager højde for indtastet tykkelse i sektion C. | D11: Opdaterede formel i C105 så den bruger D26 (sum af D23:D25) når mode='Lagtykkelser', ellers C46 (dimensionerende fra opslagstabel). | E11: Ny formel: ="Bærelagstykkelse uarmeret: "&IF($C$21="Lagtykkelser",ROUND($D$26,0),ROUND($C$46,0))&" mm". Verificeret: viser nu 800 mm (sum af D23=300+D24=500) i Lagtykkelser-mode. | F11: Formel opdateret; viser brugerens indtastede sum 800 mm i Lagtykkelser-mode.
A12: 11 | B12: 46168 | C12: Slet hele Sektion I 'Snittegning' på fane 2 Dimensionering inkl. alt der refererer til den, og omdøb Sektion J til Sektion I. | D12: Slettede rækker 89-120 på '2. Dimensionering' (header + beskrivelse + selve snittegningen + signaturforklaring). Sektion J 'Udførelseskrav' rykkede op til række 89 og er omdøbt til 'I. Udførelseskrav for dit valg'. | E12: Verificeret at M10:N12 (lag-offset, Eo-kolonneindeks, Eu-række-match) ikke er relateret til Snittegning men er kritiske mellemregninger for N15/N16/N26/N27 — disse blev efter brugerens valg bevaret. Tjekkede '3. Sådan beregnes det' og Forsiden for tekstreferencer til 'Sektion I'/'Snittegning' — ingen fundet (kun selve B89/B90 på fane 2 som blev slettet). Sletningen brugte Range('89:120').delete(shiftUp). | F12: Sektion I er nu Udførelseskrav (tidl. J). Hovedberegningen kører videre: T_uarmeret=1000 mm, T_armeret=579 mm, reduktion=421 mm. Ingen #REF!/#VALUE!-fejl på arket.
A13: 12 | B13: 46168 | C13: Lever en kortfattet men teknisk komplet beskrivelse af projektarket som .md-fil, til brug som udgangspunkt for at bygge en app. | D13: Læste fane 4-7 (korrektionsfaktorer, materialer, geonet-DB, opslagstabeller) og samlede en 12-sektion specifikation i geonet_app_specifikation.md. Inkluderer beregningsalgoritme, datatabeller, validering, UI-arkitektur, kildedokumenter og en konkret test-vektor. | E13: Specifikationen dækker: gyldighedsområder, input-grupper A-E, 7-trins beregning med lineaer interpolation i designdiagrammet, 6 datatabel-strukturer (T_basis-tabel, materiale-DB, geonet-DB, belastningsklasser, Cv→Eu, korrektionsfaktorer), produkt-klasse-matrix, advarsler, og en verificeret test-vektor (Cv=54, Eo=120, TX160, 2 lag → T_uarm=1000, T_arm=579 mm). Fil: 16,6 kB. | F13: MD-fil leveret som download. Ingen ændringer på projektarket selv.
... A17: 16 | B17: 46181 | C17: Giv eksempel på hvordan tabel 7.1 er udfyldt — én aflæst direkte og én interpoleret værdi. | D17: Leverede to gennemregnede eksempler i chatten baseret på rådata fra diagram 1 (Eo=30, Uarmeret) i 7.2. | E17: Eksempel 1 (aflæst direkte): C17 = 60 cm — Eu=10 MPa matcher rådata-punkt (B43=60, C43=10) præcis, så tykkelsen aflæses direkte uden interpolation. Eksempel 2 (interpoleret): C12 = 96.7 cm — Eu=4 MPa findes ikke i rådata; ligger mellem Eu=5 (B46=90 cm) og Eu=3.5 (B47=100 cm), så lineær interpolation giver T = 90 + (5-4)/(5-3.5)*(100-90) = 96.67 ≈ 96.7 cm. Begge tal beregnes af samme LET-formel i AJ-matricen via euhigh/eulow + tilsvarende thigh/tlow. | F17: Forklaring leveret i chat med trin-for-trin udregning. Ingen ændringer i arket.

Sheet 1. Forside
B2: Geonet Dimensioneringsværktøj — Version 1.1
B4: Dimensionering af ubundne bærelag i vejopbygninger med geonet-armering
B6: Dette værktøj beregner krævet bærelagstykkelse i en vejopbygning, hvor geonet anvendes som armering. Værktøjet er baseret på publicerede designdiagrammer fra GS-GRID / E'GRID Designmanual (okt. 2025) og Tensar Geonet Designmanual (sept. 2024), kombineret med en friktionsvinkel-korrektion fra Byggros' interne rådata-grundlag.
B10: Sådan bruger du værktøjet
B12: 1. | C12: Gå til fane "2. Dimensionering" og udfyld de blå inputfelter.
B13: 2. | C13: Sektion A: Indtast underbundens bæreevne — enten direkte (Eu) eller via vingestyrke (Cv).
B14: 3. | C14: Sektion B: Vælg en belastningsklasse (1-6) eller indtast Eo direkte.
B15: 4. | C15: Sektion C: Vælg bærelagsmateriale(r) fra dropdown — op til 3 lag med procentvis fordeling. Friktionsvinklen beregnes som vægtet gennemsnit. Alternativt kan du indtaste phi direkte.
B16: 5. | C16: Sektion D: Vælg armering — 19 produkter er tilgængelige, plus "Anden armering (manuel)" hvor du selv indtaster korrektionsfaktor.
B17: 6. | C17: Sektion E: Vælg lagopbygning (1 lag, 2 lag eller flere lag).
B18: 7. | C18: Sektion F: Aflæs resultatet — bærelagstykkelse vises som et interval (nedre/øvre).
B19: 8. | C19: Sektion G: Tjek advarsler. Se "3. Sådan beregnes det" for trin-for-trin gennemgang af din beregning.
B21: Forudsætninger og begrænsninger
B22: • | C22: Dimensioneringen forudsætter velgraduerede friktionsmaterialer som bærelag (phi > 35°).
B23: • | C23: Underbundens E-modul skal være Eu = 3 - 45 MPa (svarer til Cv ≈ 5 - 250 kN/m²).
B24: • | C24: Krævet E-modul på toppen af bærelaget skal være Eo = 30 - 150 MPa (svarer til belastningsklasse 1-6).
B25: • | C25: Vejen forudsættes at have dynamisk (trafik-) belastning. Værktøjet er IKKE egnet til statisk belastede konstruktioner såsom pæledæmninger eller forbelastede vejdæmninger.
B26: • | C26: Resultatet er en projekteringsmæssig dimensionering — for komplekse forhold (blød underbund, høj grundvandsstand, særlige belastninger) skal en geotekniker konsulteres.
B27: • | C27: Bemærk: Værktøjet bruger designmanualernes officielle korrektionsfaktorer som standard. Disse kan overstyres på fane "4. Korrektionsfaktorer".
B29: Kildedokumenter
B30: Dokument | C30: Dato/version
B31: GS-GRID / E'GRID Designmanual | C31: Okt. 2025 | F31: Officielle korrektionsfaktorer og designdiagrammer 1-6 (digitaliseret)
B32: Tensar Geonet Designmanual | C32: Sept. 2024 | F32: Korrektionsfaktorer for Tensar-serien (SS30, TX150-160, HX5.5-165, NX750-850)
B33: BG Designmanual input til program (AKK) | C33: 21/12-2016 | F33: Phi-korrektion (−2%/grad) og skærver-tabel til krydsvalidering
B34: Datablade: TX160, GS-GRID biaxial, GS-GRID SX | C34: 2024-2025 | F34: Tekniske data om maskestørrelse, max kornstørrelse mv.
B36: Versionshistorik
B37: Version | C37: Dato | D37: Ændring
B38: 1.0 | C38: 19/05-2026 | D38: Første udgivelse. Baseret på digitaliserede designdiagrammer fra GS-GRID/E'GRID Designmanual.
B40: Farvekoder i værktøjet
B41: Blå tekst | C41: Brugerinput — celler du selv udfylder
B42: Sort tekst | C42: Beregnede værdier og formler
B43: Grøn tekst | C43: Krydshenvisning mellem faneblade
B44: Gul baggrund (lys) | C44: Inputfelter der kræver din opmærksomhed
B45: Gul baggrund (medium) | C45: Hovedresultat — den anbefalede dimensionering
B46: Orange baggrund | C46: Advarsler eller fejlmeddelelser
B47: Grå baggrund | C47: Værdier aflæst fra diagrammer (mindre præcise)
B50: Udarbejdet af Dan Strand - BG Byggros A/S, Østbirkvej 2, 5240 Odense NØ.

Sheet 2. Dimensionering
B1: 2. Dimensionering — Beregning af bærelagstykkelse
B3: Udfyld de blå inputfelter nedenfor. Resultatet vises automatisk i Sektion F. Læs forklaringen af beregningen på fane "3. Sådan beregnes det". | M3: --- Mellemregninger ---
B5: A. Underbund (råjordsplanum) | M5: Eu_input (MPa): | N5: =$C$11 -> 10
B6: Vælg om du indtaster Eu direkte (pladebelastning) eller via vingestyrke Cv. | M6: Eo_input (MPa): | N6: =$C$17 -> 150
B7: Indtastningsmetode: | C7: Direkte (Eu) | M7: φ_input (°): | N7: =$C$30 -> 37.5
B8: Vingestyrke Cv: | C8: 54 | D8: (udfyldes hvis "Via vingestyrke" valgt) | M8: Lag_input: | N8: =$C$43 -> 2 lag/flere lag
B9: Eu (direkte): | C9: 10 | D9: (udfyldes hvis "Direkte" valgt)
B10: Afledt Eu (fra Cv): | C10: =IF(C7="Via vingestyrke (Cv)",IFERROR(IF(ISBLANK(C8),"",INDEX('7. Opslagstabeller'!$B$107:$D$112,MATCH(C8,INDEX('7. Opslagstabeller'!$B$107:$D$112,0,1),1),3)),"-"),"-") -> - | D10: (beregnes automatisk) | M10: Lag-offset (0/1/2): | N10: =IF($N$8="1 lag",1,2) -> 2
B11: → Eu brugt i beregning: | C11: =IF(C7="Direkte (Eu)",C9,C10) -> 10 | M11: Eo→kolonneindex (U): | N11: =IF($N$6<=30,2,IF($N$6<=45,5,IF($N$6<=60,8,IF($N$6<=80,11,IF($N$6<=120,14,17))))) -> 17
M12: Eu række-match: | N12: =MATCH($N$5,'7. Opslagstabeller'!$B$10:$B$27,1) -> 8
B13: B. Krav til overflade (E-modul på toppen af bærelaget) | M13: Eu_lower (MPa): | N13: =INDEX('7. Opslagstabeller'!$B$10:$B$27,$N$12) -> 10
B14: Vælg en belastningsklasse fra dropdown, eller indtast Eo direkte. | M14: Eu_upper (MPa): | N14: =IFERROR(INDEX('7. Opslagstabeller'!$B$10:$B$27,$N$12+1),"") -> 12
B15: Belastningsklasse: | C15: 6 - Meget tung trafik (Eo=150) | M15: T_low (cm): | N15: =IFERROR(IF(ISNUMBER(INDEX('7. Opslagstabeller'!$B$10:$T$27,$N$12,$N$11+$N$10)),INDEX('7. Opslagstabeller'!$B$10:$T$27,$N$12,$N$11+$N$10),""),"") -> 66.7
B16: Eo (direkte): | D16: (udfyldes hvis "Indtast Eo direkte" valgt) | M16: T_high (cm): | N16: =IFERROR(IF(ISNUMBER(INDEX('7. Opslagstabeller'!$B$10:$T$27,$N$12+1,$N$11+$N$10)),INDEX('7. Opslagstabeller'!$B$10:$T$27,$N$12+1,$N$11+$N$10),""),"") -> 60
B17: → Eo brugt i beregning: | C17: =IF(C15="Indtast Eo direkte",C16,IFERROR(VALUE(MID(C15,FIND("Eo=",C15)+3,FIND(")",C15,FIND("Eo=",C15))-FIND("Eo=",C15)-3)),"")) -> 150 | M17: T_basis (cm): | N17: =IFERROR(IF(AND(ISNUMBER($N$15),ISNUMBER($N$16),ISNUMBER($N$14),$N$14<>$N$13),$N$15+($N$5-$N$13)/($N$14-$N$13)*($N$16-$N$15),IF(ISNUMBER($N$15),$N$15,"")),"") -> 66.7
M18: T_basis (mm): | N18: =IFERROR($N$17*10,"") -> 667
B19: C. Bærelagsmateriale (op til 3 lag eller manuel φ)
B20: Vælg indtastningsmetode nedenfor. PROCENT: angiv vægtning mellem materialer (sum 100%). LAGTYKKELSER: angiv konkrete lagtykkelser i mm — så låses op for plan-sammenligning og reduktionsstrategi (Sektion H). | M20: φ-korrektion: | N20: ='4. Korrektionsfaktorer'!$E$7*($N$7-35) -> -0.05
B21: Indtastningsmetode: | C21: Lagtykkelser | E21: ← skift mellem procentvis vægtning og konkrete lagtykkelser | M21: Net-korrektion: | N21: =$C$39 -> -0.1
B22: Materiale | C22: Andel (%) | D22: Tykkelse (mm) | E22: φ (°) | F22: Lagtype | M22: Samlet faktor: | N22: =1+$N$20+$N$21 -> 0.85
B23: SG I 0-32 | C23: 1 | D23: 300 | E23: =IFERROR(VLOOKUP(B23,'5. DB Materialer'!$B$6:$F$18,2,FALSE()),"") -> 40 | F23: =IFERROR(VLOOKUP(B23,'5. DB Materialer'!$B$6:$F$18,4,FALSE()),"") -> Bærelag | M23: T_armeret (mm): | N23: =IFERROR($N$18*$N$22,"") -> 566.95
B24: Bundsand | D24: 300 | E24: =IFERROR(VLOOKUP(B24,'5. DB Materialer'!$B$6:$F$18,2,FALSE()),"") -> 35 | F24: =IFERROR(VLOOKUP(B24,'5. DB Materialer'!$B$6:$F$18,4,FALSE()),"") -> Bundsikring
E25: =IFERROR(VLOOKUP(B25,'5. DB Materialer'!$B$6:$F$18,2,FALSE()),"") | F25: =IFERROR(VLOOKUP(B25,'5. DB Materialer'!$B$6:$F$18,4,FALSE()),"")
B26: Sum: | C26: =SUM(C23:C25) -> 1 | D26: =SUM(D23:D25) -> 600 | E26: =IF($C$21="Procent",IF(ABS($C$26-1)>0.001,"⚠ Sum skal være 100% i Procent-mode",""),IF($D$26=0,"⚠ Indtast lagtykkelser i mm","Total opbygning: "&TEXT($D$26,"0")&" mm")) -> Total opbygning: 600 mm | M26: T_uarm_low (cm): | N26: =IFERROR(IF(ISNUMBER(INDEX('7. Opslagstabeller'!$B$10:$T$27,$N$12,$N$11)),INDEX('7. Opslagstabeller'!$B$10:$T$27,$N$12,$N$11),""),"") -> 110
B27: Lagstruktur: | C27: =IF($C$21="Procent","",IF(AND(F23="Bundsikring",F24="Bærelag"),"⚠ Lag 1 er bundsikring og lag 2 er bærelag — har du byttet rækkefølgen? Bærelag skal stå øverst.",IF(AND(F24="Bundsikring",F25="Bærelag"),"⚠ Lag 2 er bundsikring og lag 3 er bærelag — har du byttet rækkefølgen?",""))) | M27: T_uarm_high (cm): | N27: =IFERROR(IF(ISNUMBER(INDEX('7. Opslagstabeller'!$B$10:$T$27,$N$12+1,$N$11)),INDEX('7. Opslagstabeller'!$B$10:$T$27,$N$12+1,$N$11),""),"") -> 100
B28: Vægtet φ (fra materialer): | C28: =IFERROR(IF($C$21="Procent",IF($C$26=0,"",SUMPRODUCT($C$23:$C$25,$E$23:$E$25)/$C$26),IF($D$26=0,"",SUMPRODUCT($D$23:$D$25,$E$23:$E$25)/$D$26)),"") -> 37.5 | M28: T_uarmeret (mm): | N28: =IFERROR(IF(AND(ISNUMBER($N$26),ISNUMBER($N$27),ISNUMBER($N$14),$N$14<>$N$13),($N$26+($N$5-$N$13)/($N$14-$N$13)*($N$27-$N$26))*10,IF(ISNUMBER($N$26),$N$26*10,"")),"") -> 1100
B29: ELLER manuel φ : | D29: (udfyldes hvis du vil overstyre den vægtede)
B30: → φ brugt i beregning: | C30: =IF(ISBLANK($C$29),$C$28,$C$29) -> 37.5
B31: φ-korrektion anvendt: | C31: =N20 -> -0.05
B32: Friktionsvinkel-korrektionen justerer basis-tykkelsen fra opslagstabellen, som er baseret på et standardmateriale med φ ≈ 35°. For hver grad over 35° reduceres tykkelsen med 2 %, og for φ under 35° øges tykkelsen tilsvarende. I beregningen anvendes den som en multiplikativ faktor på T_basis sammen med net-korrektionen: T_armeret = T_basis × (1 + φ-korrektion + net-korrektion). En negativ værdi betyder der reduceres i tykkelsen.
M33: --- Reduktionsstrategi ---
B34: D. Armering | M34: Sum bærelag (mm): | N34: =SUMIF(F23:F25,"Bærelag",D23:D25) -> 300
B35: Vælg geonet-produkt. Korrektionsfaktoren slås automatisk op. Vælg "Anden armering" for manuelt indtastet korrektion (fx for konkurrentprodukter). | M35: Sum bundsikring (mm): | N35: =SUMIF(F23:F25,"Bundsikring",D23:D25) -> 300
B36: Geonet: | C36: GS-GRID SX170 | E36: {=_xlfn.LET( _xlpm.eo, $C$17, _xlpm.net, $C$36, _xlpm.klasse, _xlfn.IFS( _xlpm.eo="", 0, _xlpm.eo<=30, 1, _xlpm.eo<=45, 2, _xlpm.eo<=60, 3, _xlpm.eo<=80, 4, _xlpm.eo<=120, 5, _xlpm.eo<=150, 6, TRUE(), 0 ), _xlpm.ertensar, ISNUMBER(SEARCH("Tensar", _xlpm.net)), _xlpm.ergsgrid, OR(ISNUMBER(SEARCH("GS-GRID", _xlpm.net)), ISNUMBER(SEARCH("E'GRID", _xlpm.net))), _xlpm.oktensar, _xlfn.IFS( _xlpm.net="Tensar TriAx TX150", AND(_xlpm.klasse>=1, _xlpm.klasse<=4), _xlpm.net="Tensar TriAx TX160", AND(_xlpm.klasse>=3, _xlpm.klasse<=6), _xlpm.net="Tensar InterAx NX750", AND(_xlpm.klasse>=5, _xlpm.klasse<=6), _xlpm.net="Tensar InterAx NX850", AND(_xlpm.klasse>=5, _xlpm.klasse<=6), _xlpm.net="Tensar HX5.5", AND(_xlpm.klasse>=1, _xlpm.klasse<=5), _xlpm.net="Tensar SS30", AND(_xlpm.klasse>=3, _xlpm.klasse<=5), _xlpm.net="Tensar HX165", AND(_xlpm.klasse>=4, _xlpm.klasse<=6), TRUE(), FALSE() ), _xlpm.okgsgrid, _xlfn.IFS( OR(_xlpm.net="GS-GRID B20/20", _xlpm.net="GS-GRID B20/20L"), AND(_xlpm.klasse>=1, _xlpm.klasse<=3), OR(_xlpm.net="GS-GRID B30/30", _xlpm.net="GS-GRID B30/30L"), AND(_xlpm.klasse>=3, _xlpm.klasse<=5), OR(_xlpm.net="GS-GRID SX160", _xlpm.net="E'GRID T6"), AND(_xlpm.klasse>=3, _xlpm.klasse<=6), OR(_xlpm.net="GS-GRID B30/30XL", _xlpm.net="GS-GRID B40/40", _xlpm.net="GS-GRID B40/40L"), AND(_xlpm.klasse>=4, _xlpm.klasse<=6), OR(_xlpm.net="GS-GRID SX170", _xlpm.net="E'GRID T7"), AND(_xlpm.klasse>=4, _xlpm.klasse<=6), _xlpm.net="E'GRID T9L", AND(_xlpm.klasse>=4, _xlpm.klasse<=6), TRUE(), FALSE() ), _xlpm.tilladteklasser, _xlfn.IFS( _xlpm.net="Tensar TriAx TX150", "1, 2, 3 og 4", _xlpm.net="Tensar TriAx TX160", "3, 4, 5 og 6", _xlpm.net="Tensar InterAx NX750", "5 og 6", _xlpm.net="Tensar InterAx NX850", "5 og 6", _xlpm.net="Tensar HX5.5", "1, 2, 3, 4 og 5", _xlpm.net="Tensar SS30", "3, 4 og 5", _xlpm.net="Tensar HX165", "4, 5 og 6", OR(_xlpm.net="GS-GRID B20/20", _xlpm.net="GS-GRID B20/20L"), "1, 2 og 3", OR(_xlpm.net="GS-GRID B30/30", _xlpm.net="GS-GRID B30/30L"), "3, 4 og 5", OR(_xlpm.net="GS-GRID SX160", _xlpm.net="E'GRID T6"), "3, 4, 5 og 6", OR(_xlpm.net="GS-GRID B30/30XL", _xlpm.net="GS-GRID B40/40", _xlpm.net="GS-GRID B40/40L"), "4, 5 og 6", OR(_xlpm.net="GS-GRID SX170", _xlpm.net="E'GRID T7"), "4, 5 og 6", _xlpm.net="E'GRID T9L", "4, 5 og 6", TRUE(), "ukendt" ), IF(_xlpm.klasse=0, "⚠ Kan ikke bestemme belastningsklasse ud fra E0="&_xlpm.eo&" (forventer 0–150 MPa).", IF(OR(_xlpm.net="", ISBLANK(_xlpm.net)), "Vælg et geonet i C34 for at få tjek mod designmanualens anbefalinger.", IF(_xlpm.ertensar, IF(_xlpm.oktensar, "✓ Det valgte geonet kan anvendes indenfor belastningsklasse "&_xlpm.tilladteklasser, "⚠ Det valgte geonet anbefales kun anvendt i belastningsklasse "&_xlpm.tilladteklasser ), IF(_xlpm.ergsgrid, IF(_xlpm.okgsgrid, "✓ Det valgte geonet kan anvendes indenfor belastningsklasse "&_xlpm.tilladteklasser, "⚠ Det valgte geonet anbefales kun anvendt i belastningsklasse "&_xlpm.tilladteklasser ), "⚠ Geonet kan ikke matches til Tensar eller GS-GRID/E'GRID. Tjek produktnavn i C34." ) ) ) ) )} -> ✓ Det valgte geonet kan anvendes indenfor belastningsklasse 4, 5 og 6 | M36: Planlagt total (mm): | N36: =IFERROR($D$26,0) -> 600
B37: Standard korrektion: | C37: =IFERROR(VLOOKUP($C$36,'6. DB Geonet'!$B$6:$J$25,4,FALSE()),0) -> -0.1 | M37: Mulig besparelse (mm): | N37: =IFERROR(MAX(0,$N$36-$C$47),0) -> 33.05
B38: Manuel korrektion: | D38: (udfyldes for "Anden armering" eller for at overstyre)
B39: → Net-korrektion: | C39: =IF(ISBLANK($C$38),$C$37,$C$38) -> -0.1
B41: E. Lagopbygning
B42: Vælg antal lag geonet.
B43: Antal lag: | C43: 2 lag/flere lag
...

Sheet 3. Sådan beregnes det
B1: 3. Sådan beregnes det — Trin-for-trin forklaring
B3: Denne fane viser nøjagtigt hvordan værktøjet er kommet frem til resultatet på fane "2. Dimensionering". Alle tal opdateres automatisk når du ændrer input. Brug denne fane til at forstå beregningen, forklare den til kunder eller dokumentere dimensioneringen i et notat.
B5: Trin 1: Underbundens bæreevne
B6: ="Vi starter med at fastlægge underbundens E-modul (Eu). Du har indtastet "&IF('2. Dimensionering'!$C$7="Direkte (Eu)","Eu direkte: "&TEXT('2. Dimensionering'!$C$11,"0")&" MPa.","vingestyrke, og denne er omsat til Eu via opslag i konverteringstabellen (fane 7.4): Eu = "&TEXT('2. Dimensionering'!$C$11,"0")&" MPa.") -> Vi starter med at fastlægge underbundens E-modul (Eu). Du har indtastet Eu direkte: 10 MPa.
B7: Eu (anvendt i beregning): | C7: ='2. Dimensionering'!$C$11 -> 10
B9: Trin 2: Krav til toppen af bærelaget
B10: ="Det krævede E-modul på toppen af bærelaget (Eo) er fastlagt ud fra belastningsklassen. "&"Du har valgt Eo = "&TEXT('2. Dimensionering'!$C$17,"0")&" MPa, som svarer til en standard belastningsklasse jf. GS-GRID Designmanual fig. 5." -> Det krævede E-modul på toppen af bærelaget (Eo) er fastlagt ud fra belastningsklassen. Du har valgt Eo = 150 MPa, som svarer til en standard belastningsklasse jf. GS-GRID Designmanual fig. 5.
B11: Eo (anvendt i beregning): | C11: ='2. Dimensionering'!$C$17 -> 150 | H11: φ
B13: Trin 3: Bærelagets friktionsvinkel
B14: ="Bærelagets friktionsvinkel (φ) er afgørende for hvor effektivt materialet kan fordele lasten. Værktøjet bruger φ = "&TEXT('2. Dimensionering'!$C$30,"0,0")&"°. "&IF('2. Dimensionering'!$C$21="Lagtykkelser","I LAGTYKKELSE-MODE er φ vægtet efter de konkrete lagtykkelser: Σ(tykkelse_i × φ_i) / Σ(tykkelse_i). ","I PROCENT-MODE er φ vægtet efter de procentvise andele af materialerne. ")&IF('2. Dimensionering'!$C$30<=35,"Dette er minimum for friktionsmaterialer.","Da φ > 35° giver dette en gunstig korrektion på bærelagstykkelsen (se trin 5).") -> Bærelagets friktionsvinkel (φ) er afgørende for hvor effektivt materialet kan fordele lasten. Værktøjet bruger φ = 37,5°. I LAGTYKKELSE-MODE er φ vægtet efter de konkrete lagtykkelser: Σ(tykkelse_i × φ_i) / Σ(tykkelse_i). Da φ > 35° giver dette en gunstig korrektion på bærelagstykkelsen (se trin 5).
B15: φ (anvendt i beregning): | C15: ='2. Dimensionering'!$C$30 -> 37.5
B17: Trin 4: Opslag i designdiagrammet
B18: ="Vi slår nu op i designdiagrammet for Eo = "&TEXT('2. Dimensionering'!$C$17,"0")&" MPa (fane 7.1). Vi vælger kurven for "&'2. Dimensionering'!$C$43&" og finder bærelagstykkelsen ved Eu = "&TEXT('2. Dimensionering'!$C$11,"0")&" MPa. Da valgt/beregnet Eu kan ligge mellem to af tabellens værdier (I dette tilfælde "&TEXT('2. Dimensionering'!$N$13,"0")&" og "&TEXT('2. Dimensionering'!$N$14,"0")&" MPa), interpoleres lineært. Hvis Eu ligger på et punkt i tabellen, aflæses tabelværdien bare direkte" -> Vi slår nu op i designdiagrammet for Eo = 150 MPa (fane 7.1). Vi vælger kurven for 2 lag/flere lag og finder bærelagstykkelsen ved Eu = 10 MPa. Da valgt/beregnet Eu kan ligge mellem to af tabellens værdier (I dette tilfælde 10 og 12 MPa), interpoleres lineært. Hvis Eu ligger på et punkt i tabellen, aflæses tabelværdien bare direkte
B19: Mellem Eu = | C19: ='2. Dimensionering'!$N$13 -> 10 | D19: =CONCATENATE("(T = ",TEXT('2. Dimensionering'!$N$15,"0")," cm)") -> (T = 67 cm)
B20: og Eu = | C20: ='2. Dimensionering'!$N$14 -> 12 | D20: =CONCATENATE("(T = ",TEXT('2. Dimensionering'!$N$16,"0")," cm)") -> (T = 60 cm)
B21: → Basis-tykkelse (evt. interpoleret): | C21: ='2. Dimensionering'!$N$18 -> 667
B23: Trin 5: Korrektion for friktionsvinkel
B24: ="Designdiagrammet er baseret på et standard friktionsmateriale med φ ≈ 35°. Hvis dit materiale har en højere φ, kan bærelaget gøres tilsvarende tyndere. Korrektionen er −2 % per grad over 35° (fra Excel-arket AKK 2016). For φ = "&TEXT('2. Dimensionering'!$C$30,"0,0")&"° giver dette en korrektion på "&TEXT('2. Dimensionering'!$N$20,"+0,0%;-0,0%")&"." -> Designdiagrammet er baseret på et standard friktionsmateriale med φ ≈ 35°. Hvis dit materiale har en højere φ, kan bærelaget gøres tilsvarende tyndere. Korrektionen er −2 % per grad over 35° (fra Excel-arket AKK 2016). For φ = 37,5° giver dette en korrektion på -5,0%.
B25: φ-korrektion anvendt: | C25: ='2. Dimensionering'!$N$20 -> -0.05
B27: Trin 6: Korrektion for armeringstype
B28: ="Designdiagrammet bruger GS-GRID SX160 / E'GRID T6 (eller TriAx TX160) som reference-armering (effektindeks 100). Hvis du har valgt en anden armering, skaleres tykkelsen op eller ned. Du har valgt: "&'2. Dimensionering'!$C$36&". Det giver en korrektion på "&TEXT('2. Dimensionering'!$C$39,"+0,0%;-0,0%")&". Bemærk: positiv = tykkere bærelag (mindre effektiv armering), negativ = tyndere bærelag (mere effektiv armering)." -> Designdiagrammet bruger GS-GRID SX160 / E'GRID T6 (eller TriAx TX160) som reference-armering (effektindeks 100). Hvis du har valgt en anden armering, skaleres tykkelsen op eller ned. Du har valgt: GS-GRID SX170. Det giver en korrektion på -10,0%. Bemærk: positiv = tykkere bærelag (mindre effektiv armering), negativ = tyndere bærelag (mere effektiv armering).
B29: Net-korrektion anvendt: | C29: ='2. Dimensionering'!$C$39 -> -0.1
B31: Trin 7: Sammensætning til dimensionerende tykkelse
B32: Vi multiplicerer basis-tykkelsen med den samlede korrektionsfaktor (1 + φ-korrektion + net-korrektion). Resultatet er den dimensionerende armerede bærelagstykkelse — det er det tal du skal bruge i projektet.
B33: =CONCATENATE("T_armeret = T_basis × (1 + φ-korr + net-korr) = ",TEXT('2. Dimensionering'!$N$18,"0")," mm × ",TEXT('2. Dimensionering'!$N$22,"0.000")," = ",TEXT('2. Dimensionering'!$C$47,"0")," mm") -> T_armeret = T_basis × (1 + φ-korr + net-korr) = 667 mm × 0.001 = 567 mm
B34: → T_armeret (dimensionerende): | C34: ='2. Dimensionering'!$C$47 -> 566.95
B41: Trin 9: Sammenligning med uarmeret opbygning
B42: =IFERROR("Hvis vi havde lavet samme opbygning UDEN armering, ville bærelaget skulle være "&TEXT('2. Dimensionering'!$C$46,"0")&" mm tykt. Med din valgte armering reduceres tykkelsen til "&TEXT('2. Dimensionering'!$C$47,"0")&" mm. Det er en reduktion på "&TEXT('2. Dimensionering'!$C$46-'2. Dimensionering'!$C$47,"0")&" mm svarende til "&TEXT(('2. Dimensionering'!$C$46-'2. Dimensionering'!$C$47)/'2. Dimensionering'!$C$46,"0%")&" — den væsentligste fordel ved at bruge geonet i denne opbygning.","(Beregning ikke mulig — tjek input på fane 2)") -> Hvis vi havde lavet samme opbygning UDEN armering, ville bærelaget skulle være 1100 mm tykt. Med din valgte armering reduceres tykkelsen til 567 mm. Det er en reduktion på 533 mm svarende til 48% — den væsentligste fordel ved at bruge geonet i denne opbygning.
B44: Trin 10: Sammenligning af din planlagte opbygning med kravene
B45: =IF('2. Dimensionering'!$C$21<>"Lagtykkelser","ⓘ Dette trin er kun aktivt i lagtykkelse-mode. Skift indtastningsmetode i Sektion C på fane 2 for at se forklaringen.","I lagtykkelse-mode har du indtastet konkrete tykkelser for hvert lag, og værktøjet kan derfor sammenligne din planlagte opbygning med både uarmeret og armeret krav. Din planlagte total er "&TEXT('2. Dimensionering'!$C$52,"0")&" mm. Sammenlignet med det uarmerede krav på "&TEXT('2. Dimensionering'!$C$46,"0")&" mm har din plan "&IF('2. Dimensionering'!$C$53>=0,"+"&TEXT('2. Dimensionering'!$C$53,"0")&" mm slæk (tilstrækkelig).",TEXT('2. Dimensionering'!$C$53,"0")&" mm — utilstrækkelig uden armering.")&" Sammenlignet med det armerede krav på "&TEXT('2. Dimensionering'!$C$47,"0")&" mm har din plan "&IF('2. Dimensionering'!$C$54>=0,"+"&TEXT('2. Dimensionering'!$C$54,"0")&" mm slæk (tilstrækkelig med armering).",TEXT('2. Dimensionering'!$C$54,"0")&" mm — utilstrækkelig selv med armering.")&" Den mulige besparelse fra din plan ved armering er dermed "&TEXT('2. Dimensionering'!$C$55,"0")&" mm.") -> I lagtykkelse-mode har du indtastet konkrete tykkelser for hvert lag, og værktøjet kan derfor sammenligne din planlagte opbygning med både uarmeret og armeret krav. Din planlagte total er 600 mm. Sammenlignet med det uarmerede krav på 1100 mm har din plan -500 mm — utilstrækkelig uden armering. Sammenlignet med det armerede krav på 567 mm har din plan +33 mm slæk (tilstrækkelig med armering). Den mulige besparelse fra din plan ved armering er dermed 33 mm.
B47: Planlagt total: | C47: ='2. Dimensionering'!$C$52 -> 600
B48: Krav uden armering: | C48: ='2. Dimensionering'!$C$46 -> 1100
B49: Krav med armering: | C49: ='2. Dimensionering'!$C$47 -> 566.95
B50: Mulig besparelse: | C50: ='2. Dimensionering'!$C$55 -> 33.05
B52: Trin 11: Reduktionsstrategi — hvor i opbygningen tages besparelsen?
B53: =IF('2. Dimensionering'!$C$21<>"Lagtykkelser","ⓘ Dette trin er kun aktivt i lagtykkelse-mode.","Når armeringen tillader at du reducerer opbygningen, skal de sparede millimeter tages et eller flere steder. Du har valgt strategien """&'2. Dimensionering'!$C$71&""". "&IF('2. Dimensionering'!$C$71="Reducer bærelag",_xlfn._LONGTEXT("Denne strategi reducerer udelukkende bærelaget/bærelagene (typisk stabilgrus eller knust beton). Hvis du har flere bærelag fordeles reduktionen proportionalt mellem dem. Bundsikringen bevares uændret. Vær opmærksom: hvis bærelaget bliver meget tyndt, kan ","dæklags-kravet på 200 mm være underskredet."),IF('2. Dimensionering'!$C$71="Reducer bundsikring",_xlfn._LONGTEXT("Denne strategi reducerer udelukkende bundsikringen, og bevarer bærelaget i sin oprindelige tykkelse. Det er ofte det praktisk mest meningsfulde valg, fordi bærelaget (stabilgrus) er det dyre kvalitetsmateriale du gerne vil beholde i fuld tykkelse for kørs","elsoverflade. Bundsikringen er det billigere drænende lag der reduceres."),IF('2. Dimensionering'!$C$71="Reducer alle proportionalt","Denne strategi reducerer alle lag med samme procent. Forholdet mellem bærelag og bundsikring bevares præcis. Det er en god strategi hvis du har specifikationer der kræver et bestemt forhold mellem lagene.","Denne strategi giver dig fuld kontrol — du indtaster selv de ønskede lagtykkelser i kolonnen ""Manuel (mm)"" på fane 2. Værktøjet validerer at den samlede tykkelse opfylder armeret krav.")))) -> Når armeringen tillader at du reducerer opbygningen, skal de sparede millimeter tages et eller flere steder. Du har valgt strategien "Manuel justering". Denne strategi giver dig fuld kontrol — du indtaster selv de ønskede lagtykkelser i kolonnen "Manuel (mm)" på fane 2. Værktøjet validerer at den samlede tykkelse opfylder armeret krav.
B55: Lag | C55: Materiale | D55: Planlagt (mm) | E55: Foreslået (mm)
B56: Lag 1 | C56: ='2. Dimensionering'!$B$23 -> SG I 0-32 | D56: ='2. Dimensionering'!$D$23 -> 300 | E56: ='2. Dimensionering'!$G$74 -> 300
B57: Lag 2 | C57: ='2. Dimensionering'!$B$24 -> Bundsand | D57: ='2. Dimensionering'!$D$24 -> 300 | E57: ='2. Dimensionering'!$G$75 -> 300
B58: Lag 3 | C58: ='2. Dimensionering'!$B$25 -> 0 | D58: ='2. Dimensionering'!$D$25 -> 0 | E58: ='2. Dimensionering'!$G$76
...

Sheet 4. Korrektionsfaktorer
B1: 4. Korrektionsfaktorer — Overstyring af standardværdier
B3: Her kan du overstyre de korrektionsfaktorer der bruges i dimensioneringsformlen. Som standard anvendes designmanualernes officielle tal. Hvis du indtaster en værdi i kolonnen "Brugerdefineret", overstyres standard-værdien — også på fane 2. For at gå tilbage til standardværdien, slet din indtastning.
B5: A. Generelle korrektionsfaktorer
B6: Beskrivelse | C6: Standard | D6: Brugerdef. | E6: Aktuelt | F6: Kilde / Bemærkning
B7: Friktionsvinkel-korrektion (pr. grad over 35°) | C7: -0.02 | E7: =IF(ISBLANK(D7),C7,D7) -> -0.02 | F7: Excel-arket BG-DATA NY (AKK 21/12-2016). Reducerer T med 2% pr. grad ekstra friktionsvinkel.
B9: Flerlags-effekt ved >1 lag geonet | C9: 0.1 | D9: Ikke relevant | E9: =C9 -> 0.1 | F9: GS-GRID / TENSAR Designmanual: flere lag geonet i bærelagstykkelser på >500 mm kan reducere den totale tykkelse yderligere med ca. 10%. I dette værktøj er effekten allerede indbygget i beregningen via opslagstabellernes kolonne '2/flere lag' på fane 7 og dermed medtaget i resultatet.
B11: B. Produktspecifikke korrektionsfaktorer for armering
B12: Disse værdier er kopieret fra fane "6. DB Geonet". Du kan overstyre dem her hvis du vil teste en alternativ vurdering. Bemærk: at ændre disse her påvirker IKKE databasen — kun det resultat værktøjet bruger. Korrektionsfaktoren er en tykkelsesjustering relativt til referenceproduktet Tensar TriAx TX160 / GS-GRID SX160 / E'GRID T6 (effektindeks 100). En positiv faktor betyder mindre effektiv armering og dermed et tykkere bærelag. Eksempel: Tensar HX5.5 har effektindeks 95 og derfor +5,0 %, hvilket betyder at den krævede bærelagstykkelse øges med 5 % i forhold til referencen, og ikke at nettet er 5 % bedre.
B13: Produkt | C13: Standard | D13: Brugerdef. | E13: Aktuelt | F13: Kilde / Bemærkning
B14: Tensar SS30 | C14: 0.1 | E14: =IF(ISBLANK(D14),C14,D14) -> 0.1 | F14: Effektindeks 90
B15: Tensar TriAx TX150 | C15: 0.1 | E15: =IF(ISBLANK(D15),C15,D15) -> 0.1 | F15: Effektindeks 90
B16: Tensar HX5.5 | C16: 0.05 | E16: =IF(ISBLANK(D16),C16,D16) -> 0.05 | F16: Effektindeks 95
B17: Tensar TriAx TX160 | C17: 0 | E17: =IF(ISBLANK(D17),C17,D17) -> 0 | F17: REFERENCE — effektindeks 100
B18: Tensar HX165 | C18: -0.05 | E18: =IF(ISBLANK(D18),C18,D18) -> -0.05 | F18: Effektindeks 105
B19: Tensar InterAx NX750 | C19: -0.1 | E19: =IF(ISBLANK(D19),C19,D19) -> -0.1 | F19: Effektindeks 110-120
B20: Tensar InterAx NX850 | C20: -0.15 | E20: =IF(ISBLANK(D20),C20,D20) -> -0.15 | F20: Effektindeks 115-130
B21: GS-GRID B20/20 | C21: 0.2 | E21: =IF(ISBLANK(D21),C21,D21) -> 0.2
B22: GS-GRID B20/20L | C22: 0.2 | E22: =IF(ISBLANK(D22),C22,D22) -> 0.2
B23: GS-GRID B30/30 | C23: 0.1 | E23: =IF(ISBLANK(D23),C23,D23) -> 0.1
B24: GS-GRID B30/30L | C24: 0.1 | E24: =IF(ISBLANK(D24),C24,D24) -> 0.1
B25: GS-GRID B30/30XL | C25: 0.1 | E25: =IF(ISBLANK(D25),C25,D25) -> 0.1
B26: GS-GRID B40/40 | C26: 0 | E26: =IF(ISBLANK(D26),C26,D26) -> 0
B27: GS-GRID B40/40L | C27: 0 | E27: =IF(ISBLANK(D27),C27,D27) -> 0
B28: GS-GRID SX160 | C28: 0 | E28: =IF(ISBLANK(D28),C28,D28) -> 0 | F28: REFERENCE
B29: GS-GRID SX170 | C29: -0.1 | E29: =IF(ISBLANK(D29),C29,D29) -> -0.1
B30: E'GRID T6 | C30: 0 | E30: =IF(ISBLANK(D30),C30,D30) -> 0 | F30: Alternativ til SX160
B31: E'GRID T7 | C31: -0.1 | E31: =IF(ISBLANK(D31),C31,D31) -> -0.1 | F31: Alternativ til SX170
B32: E'GRID T9L | C32: -0.1 | E32: =IF(ISBLANK(D32),C32,D32) -> -0.1

Sheet 5. DB Materialer
B1: 5. Database: Bærelagsmaterialer
B3: Denne database indeholder de typiske bærelagsmaterialer med tilhørende friktionsvinkel (φ), maksimal kornstørrelse og lagtype. Lagtypen (Bærelag eller Bundsikring) bruges af værktøjet til automatisk at placere geonettet korrekt i opbygningen — bærelag øverst, bundsikring nederst, geonet typisk i laggrænsen mellem dem. Du kan tilføje egne materialer ved at indsætte en ny række (men brug ikke materialenavne der allerede findes).
B5: Materiale | C5: φ (°) | D5: Max korn (mm) | E5: Lagtype | F5: Anvendelse
B6: Bundsand | C6: 35 | D6: 8 | E6: Bundsikring | F6: Bundlag, friktionsmateriale
B7: Bundgrus 0-80 | C7: 38 | D7: 80 | E7: Bundsikring | F7: Bundsikring
B8: SG I 0-32 | C8: 40 | D8: 32 | E8: Bærelag | F8: Stabilgrus, øvre bærelag
B9: SG II 0-32 | C9: 40 | D9: 32 | E9: Bærelag | F9: Stabilgrus
B10: Knust beton 0-32 | C10: 40 | D10: 32 | E10: Bærelag | F10: Genbrugsmateriale, øvre bærelag
B11: Skærver 0-32 | C11: 45 | D11: 32 | E11: Bærelag | F11: Topbærelag, høj kvalitet
B12: Skærver 0-64 | C12: 45 | D12: 64 | E12: Bærelag | F12: Bærelag
B13: Skærver 0-90 | C13: 45 | D13: 90 | E13: Bærelag | F13: Bærelag (kan dog også anvendes som bundsikring)
B14: Skærver 0-120 | C14: 45 | D14: 120 | E14: Bundsikring | F14: Bundsikring
B15: Skærver 0-150 | C15: 45 | D15: 150 | E15: Bundsikring | F15: Bundsikring grov
B16: Skærver 0-200 | C16: 45 | D16: 200 | E16: Bundsikring | F16: Bundsikring meget grov
B17: Skærver 0-250 | C17: 45 | D17: 250 | E17: Bundsikring | F17: Bundsikring ekstrem
B18: Manuel indtastning | F18: Vælg denne mulighed på fane 2 for at indtaste φ direkte
B20: Farvekoder for lagtype:
C21: Bærelag (øvre lag, stabilgrus eller fine skærver)
C22: Bundsikring (nedre lag, sand/grus eller grove skærver)

Sheet 6. DB Geonet
B1: 6. Database: Geonet
B3: Komplet produktkatalog over Tensar- og GS-GRID/E'GRID-geonet. Korrektionsfaktorerne er fra de officielle designmanualer (sept. 2024 og okt. 2025) og udtrykker hvor meget bærelagstykkelsen ændrer sig i forhold til reference-produktet (effektindeks 100 = TX160/SX160). En positiv faktor betyder et mindre effektivt net (tykkere bærelag), en negativ faktor betyder mere effektivt net (tyndere bærelag). Tekniske data er fra databladene. Tomme felter = data ikke tilgængelige.
L4: Anbefalet belastningsklasse
B5: Produkt | C5: Serie | D5: Type | E5: Korrektion | F5: Maske/Pitch | G5: Max korn (mm) | H5: Min dæklag (cm) | I5: Rullebredde (m) | J5: Bemærkning | K5: Anbef. tilslag (mm) | L5: 1 | M5: 2 | N5: 3 | O5: 4 | P5: 5 | Q5: 6
B6: Tensar SS30 | C6: Tensar | D6: Biaxialt | E6: 0.1 | F6: Ej oplyst | G6: Ej oplyst | H6: 20 | I6: Ej oplyst | J6: Effektindeks 90 | K6: Ej oplyst | L6: {=IF(OR($B6="Anden armering",$B6=""),"",IF(_xlfn.IFS( $B6="Tensar TriAx TX150",AND(L$5>=1,L$5<=4), $B6="Tensar TriAx TX160",AND(L$5>=3,L$5<=6), $B6="Tensar InterAx NX750",AND(L$5>=5,L$5<=6), $B6="Tensar InterAx NX850",AND(L$5>=5,L$5<=6), $B6="Tensar HX5.5",AND(L$5>=1,L$5<=5), $B6="Tensar SS30",AND(L$5>=3,L$5<=5), $B6="Tensar HX165",AND(L$5>=4,L$5<=6), OR($B6="GS-GRID B20/20",$B6="GS-GRID B20/20L"),AND(L$5>=1,L$5<=3), OR($B6="GS-GRID B30/30",$B6="GS-GRID B30/30L"),AND(L$5>=3,L$5<=5), OR($B6="GS-GRID SX160",$B6="E'GRID T6"),AND(L$5>=3,L$5<=6), OR($B6="GS-GRID B30/30XL",$B6="GS-GRID B40/40",$B6="GS-GRID B40/40L"),AND(L$5>=4,L$5<=6), OR($B6="GS-GRID SX170",$B6="E'GRID T7"),AND(L$5>=4,L$5<=6), $B6="E'GRID T9L",AND(L$5>=4,L$5<=6), TRUE,FALSE ),"x","") )} | M6: {=IF(OR($B6="Anden armering",$B6=""),"",IF(_xlfn.IFS( $B6="Tensar TriAx TX150",AND(M$5>=1,M$5<=4), $B6="Tensar TriAx TX160",AND(M$5>=3,M$5<=6), $B6="Tensar InterAx NX750",AND(M$5>=5,M$5<=6), $B6="Tensar InterAx NX850",AND(M$5>=5,M$5<=6), $B6="Tensar HX5.5",AND(M$5>=1,M$5<=5), $B6="Tensar SS30",AND(M$5>=3,M$5<=5), $B6="Tensar HX165",AND(M$5>=4,M$5<=6), OR($B6="GS-GRID B20/20",$B6="GS-GRID B20/20L"),AND(M$5>=1,M$5<=3), OR($B6="GS-GRID B30/30",$B6="GS-GRID B30/30L"),AND(M$5>=3,M$5<=5), OR($B6="GS-GRID SX160",$B6="E'GRID T6"),AND(M$5>=3,M$5<=6), OR($B6="GS-GRID B30/30XL",$B6="GS-GRID B40/40",$B6="GS-GRID B40/40L"),AND(M$5>=4,M$5<=6), OR($B6="GS-GRID SX170",$B6="E'GRID T7"),AND(M$5>=4,M$5<=6), $B6="E'GRID T9L",AND(M$5>=4,M$5<=6), TRUE,FALSE ),"x","") )} | N6: {=IF(OR($B6="Anden armering",$B6=""),"",IF(_xlfn.IFS( $B6="Tensar TriAx TX150",AND(N$5>=1,N$5<=4), $B6="Tensar TriAx TX160",AND(N$5>=3,N$5<=6), $B6="Tensar InterAx NX750",AND(N$5>=5,N$5<=6), $B6="Tensar InterAx NX850",AND(N$5>=5,N$5<=6), $B6="Tensar HX5.5",AND(N$5>=1,N$5<=5), $B6="Tensar SS30",AND(N$5>=3,N$5<=5), $B6="Tensar HX165",AND(N$5>=4,N$5<=6), OR($B6="GS-GRID B20/20",$B6="GS-GRID B20/20L"),AND(N$5>=1,N$5<=3), OR($B6="GS-GRID B30/30",$B6="GS-GRID B30/30L"),AND(N$5>=3,N$5<=5), OR($B6="GS-GRID SX160",$B6="E'GRID T6"),AND(N$5>=3,N$5<=6), OR($B6="GS-GRID B30/30XL",$B6="GS-GRID B40/40",$B6="GS-GRID B40/40L"),AND(N$5>=4,N$5<=6), OR($B6="GS-GRID SX170",$B6="E'GRID T7"),AND(N$5>=4,N$5<=6), $B6="E'GRID T9L",AND(N$5>=4,N$5<=6), TRUE,FALSE ),"x","") )} -> x | O6: {=IF(OR($B6="Anden armering",$B6=""),"",IF(_xlfn.IFS( $B6="Tensar TriAx TX150",AND(O$5>=1,O$5<=4), $B6="Tensar TriAx TX160",AND(O$5>=3,O$5<=6), $B6="Tensar InterAx NX750",AND(O$5>=5,O$5<=6), $B6="Tensar InterAx NX850",AND(O$5>=5,O$5<=6), $B6="Tensar HX5.5",AND(O$5>=1,O$5<=5), $B6="Tensar SS30",AND(O$5>=3,O$5<=5), $B6="Tensar HX165",AND(O$5>=4,O$5<=6), OR($B6="GS-GRID B20/20",$B6="GS-GRID B20/20L"),AND(O$5>=1,O$5<=3), OR($B6="GS-GRID B30/30",$B6="GS-GRID B30/30L"),AND(O$5>=3,O$5<=5), OR($B6="GS-GRID SX160",$B6="E'GRID T6"),AND(O$5>=3,O$5<=6), OR($B6="GS-GRID B30/30XL",$B6="GS-GRID B40/40",$B6="GS-GRID B40/40L"),AND(O$5>=4,O$5<=6), OR($B6="GS-GRID SX170",$B6="E'GRID T7"),AND(O$5>=4,O$5<=6), $B6="E'GRID T9L",AND(O$5>=4,O$5<=6), TRUE,FALSE ),"x","") )} -> x | P6: {=IF(OR($B6="Anden armering",$B6=""),"",IF(_xlfn.IFS( $B6="Tensar TriAx TX150",AND(P$5>=1,P$5<=4), $B6="Tensar TriAx TX160",AND(P$5>=3,P$5<=6), $B6="Tensar InterAx NX750",AND(P$5>=5,P$5<=6), $B6="Tensar InterAx NX850",AND(P$5>=5,P$5<=6), $B6="Tensar HX5.5",AND(P$5>=1,P$5<=5), $B6="Tensar SS30",AND(P$5>=3,P$5<=5), $B6="Tensar HX165",AND(P$5>=4,P$5<=6), OR($B6="GS-GRID B20/20",$B6="GS-GRID B20/20L"),AND(P$5>=1,P$5<=3), OR($B6="GS-GRID B30/30",$B6="GS-GRID B30/30L"),AND(P$5>=3,P$5<=5), OR($B6="GS-GRID SX160",$B6="E'GRID T6"),AND(P$5>=3,P$5<=6), OR($B6="GS-GRID B30/30XL",$B6="GS-GRID B40/40",$B6="GS-GRID B40/40L"),AND(P$5>=4,P$5<=6), OR($B6="GS-GRID SX170",$B6="E'GRID T7"),AND(P$5>=4,P$5<=6), $B6="E'GRID T9L",AND(P$5>=4,P$5<=6), TRUE,FALSE ),"x","") )} -> x | Q6: {=IF(OR($B6="Anden armering",$B6=""),"",IF(_xlfn.IFS( $B6="Tensar TriAx TX150",AND(Q$5>=1,Q$5<=4), $B6="Tensar TriAx TX160",AND(Q$5>=3,Q$5<=6), $B6="Tensar InterAx NX750",AND(Q$5>=5,Q$5<=6), $B6="Tensar InterAx NX850",AND(Q$5>=5,Q$5<=6), $B6="Tensar HX5.5",AND(Q$5>=1,Q$5<=5), $B6="Tensar SS30",AND(Q$5>=3,Q$5<=5), $B6="Tensar HX165",AND(Q$5>=4,Q$5<=6), OR($B6="GS-GRID B20/20",$B6="GS-GRID B20/20L"),AND(Q$5>=1,Q$5<=3), OR($B6="GS-GRID B30/30",$B6="GS-GRID B30/30L"),AND(Q$5>=3,Q$5<=5), OR($B6="GS-GRID SX160",$B6="E'GRID T6"),AND(Q$5>=3,Q$5<=6), OR($B6="GS-GRID B30/30XL",$B6="GS-GRID B40/40",$B6="GS-GRID B40/40L"),AND(Q$5>=4,Q$5<=6), OR($B6="GS-GRID SX170",$B6="E'GRID T7"),AND(Q$5>=4,Q$5<=6), $B6="E'GRID T9L",AND(Q$5>=4,Q$5<=6), TRUE,FALSE ),"x","") )}
B7: Tensar TriAx TX150 | C7: Tensar | D7: Triaxialt | E7: 0.1 | F7: Ej oplyst | G7: Ej oplyst | H7: 20 | I7: Ej oplyst | J7: Effektindeks 90 | K7: Ej oplyst | L7: {=IF(OR($B7="Anden armering",$B7=""),"",IF(_xlfn.IFS( $B7="Tensar TriAx TX150",AND(L$5>=1,L$5<=4), $B7="Tensar TriAx TX160",AND(L$5>=3,L$5<=6), $B7="Tensar InterAx NX750",AND(L$5>=5,L$5<=6), $B7="Tensar InterAx NX850",AND(L$5>=5,L$5<=6), $B7="Tensar HX5.5",AND(L$5>=1,L$5<=5), $B7="Tensar SS30",AND(L$5>=3,L$5<=5), $B7="Tensar HX165",AND(L$5>=4,L$5<=6), OR($B7="GS-GRID B20/20",$B7="GS-GRID B20/20L"),AND(L$5>=1,L$5<=3), OR($B7="GS-GRID B30/30",$B7="GS-GRID B30/30L"),AND(L$5>=3,L$5<=5), OR($B7="GS-GRID SX160",$B7="E'GRID T6"),AND(L$5>=3,L$5<=6), OR($B7="GS-GRID B30/30XL",$B7="GS-GRID B40/40",$B7="GS-GRID B40/40L"),AND(L$5>=4,L$5<=6), OR($B7="GS-GRID SX170",$B7="E'GRID T7"),AND(L$5>=4,L$5<=6), $B7="E'GRID T9L",AND(L$5>=4,L$5<=6), TRUE,FALSE ),"x","") )} -> x | M7: {=IF(OR($B7="Anden armering",$B7=""),"",IF(_xlfn.IFS( $B7="Tensar TriAx TX150",AND(M$5>=1,M$5<=4), $B7="Tensar TriAx TX160",AND(M$5>=3,M$5<=6), $B7="Tensar InterAx NX750",AND(M$5>=5,M$5<=6), $B7="Tensar InterAx NX850",AND(M$5>=5,M$5<=6), $B7="Tensar HX5.5",AND(M$5>=1,M$5<=5), $B7="Tensar SS30",AND(M$5>=3,M$5<=5), $B7="Tensar HX165",AND(M$5>=4,M$5<=6), OR($B7="GS-GRID B20/20",$B7="GS-GRID B20/20L"),AND(M$5>=1,M$5<=3), OR($B7="GS-GRID B30/30",$B7="GS-GRID B30/30L"),AND(M$5>=3,M$5<=5), OR($B7="GS-GRID SX160",$B7="E'GRID T6"),AND(M$5>=3,M$5<=6), OR($B7="GS-GRID B30/30XL",$B7="GS-GRID B40/40",$B7="GS-GRID B40/40L"),AND(M$5>=4,M$5<=6), OR($B7="GS-GRID SX170",$B7="E'GRID T7"),AND(M$5>=4,M$5<=6), $B7="E'GRID T9L",AND(M$5>=4,M$5<=6), TRUE,FALSE ),"x","") )} -> x | N7: {=IF(OR($B7="Anden armering",$B7=""),"",IF(_xlfn.IFS( $B7="Tensar TriAx TX150",AND(N$5>=1,N$5<=4), $B7="Tensar TriAx TX160",AND(N$5>=3,N$5<=6), $B7="Tensar InterAx NX750",AND(N$5>=5,N$5<=6), $B7="Tensar InterAx NX850",AND(N$5>=5,N$5<=6), $B7="Tensar HX5.5",AND(N$5>=1,N$5<=5), $B7="Tensar SS30",AND(N$5>=3,N$5<=5), $B7="Tensar HX165",AND(N$5>=4,N$5<=6), OR($B7="GS-GRID B20/20",$B7="GS-GRID B20/20L"),AND(N$5>=1,N$5<=3), OR($B7="GS-GRID B30/30",$B7="GS-GRID B30/30L"),AND(N$5>=3,N$5<=5), OR($B7="GS-GRID SX160",$B7="E'GRID T6"),AND(N$5>=3,N$5<=6), OR($B7="GS-GRID B30/30XL",$B7="GS-GRID B40/40",$B7="GS-GRID B40/40L"),AND(N$5>=4,N$5<=6), OR($B7="GS-GRID SX170",$B7="E'GRID T7"),AND(N$5>=4,N$5<=6), $B7="E'GRID T9L",AND(N$5>=4,N$5<=6), TRUE,FALSE ),"x","") )} -> x | O7: {=IF(OR($B7="Anden armering",$B7=""),"",IF(_xlfn.IFS( $B7="Tensar TriAx TX150",AND(O$5>=1,O$5<=4), $B7="Tensar TriAx TX160",AND(O$5>=3,O$5<=6), $B7="Tensar InterAx NX750",AND(O$5>=5,O$5<=6), $B7="Tensar InterAx NX850",AND(O$5>=5,O$5<=6), $B7="Tensar HX5.5",AND(O$5>=1,O$5<=5), $B7="Tensar SS30",AND(O$5>=3,O$5<=5), $B7="Tensar HX165",AND(O$5>=4,O$5<=6), OR($B7="GS-GRID B20/20",$B7="GS-GRID B20/20L"),AND(O$5>=1,O$5<=3), OR($B7="GS-GRID B30/30",$B7="GS-GRID B30/30L"),AND(O$5>=3,O$5<=5), OR($B7="GS-GRID SX160",$B7="E'GRID T6"),AND(O$5>=3,O$5<=6), OR($B7="GS-GRID B30/30XL",$B7="GS-GRID B40/40",$B7="GS-GRID B40/40L"),AND(O$5>=4,O$5<=6), OR($B7="GS-GRID SX170",$B7="E'GRID T7"),AND(O$5>=4,O$5<=6), $B7="E'GRID T9L",AND(O$5>=4,O$5<=6), TRUE,FALSE ),"x","") )} -> x | P7: {=IF(OR($B7="Anden armering",$B7=""),"",IF(_xlfn.IFS( $B7="Tensar TriAx TX150",AND(P$5>=1,P$5<=4), $B7="Tensar TriAx TX160",AND(P$5>=3,P$5<=6), $B7="Tensar InterAx NX750",AND(P$5>=5,P$5<=6), $B7="Tensar InterAx NX850",AND(P$5>=5,P$5<=6), $B7="Tensar HX5.5",AND(P$5>=1,P$5<=5), $B7="Tensar SS30",AND(P$5>=3,P$5<=5), $B7="Tensar HX165",AND(P$5>=4,P$5<=6), OR($B7="GS-GRID B20/20",$B7="GS-GRID B20/20L"),AND(P$5>=1,P$5<=3), OR($B7="GS-GRID B30/30",$B7="GS-GRID B30/30L"),AND(P$5>=3,P$5<=5), OR($B7="GS-GRID SX160",$B7="E'GRID T6"),AND(P$5>=3,P$5<=6), OR($B7="GS-GRID B30/30XL",$B7="GS-GRID B40/40",$B7="GS-GRID B40/40L"),AND(P$5>=4,P$5<=6), OR($B7="GS-GRID SX170",$B7="E'GRID T7"),AND(P$5>=4,P$5<=6), $B7="E'GRID T9L",AND(P$5>=4,P$5<=6), TRUE,FALSE ),"x","") )} | Q7: {=IF(OR($B7="Anden armering",$B7=""),"",IF(_xlfn.IFS( $B7="Tensar TriAx TX150",AND(Q$5>=1,Q$5<=4), $B7="Tensar TriAx TX160",AND(Q$5>=3,Q$5<=6), $B7="Tensar InterAx NX750",AND(Q$5>=5,Q$5<=6), $B7="Tensar InterAx NX850",AND(Q$5>=5,Q$5<=6), $B7="Tensar HX5.5",AND(Q$5>=1,Q$5<=5), $B7="Tensar SS30",AND(Q$5>=3,Q$5<=5), $B7="Tensar HX165",AND(Q$5>=4,Q$5<=6), OR($B7="GS-GRID B20/20",$B7="GS-GRID B20/20L"),AND(Q$5>=1,Q$5<=3), OR($B7="GS-GRID B30/30",$B7="GS-GRID B30/30L"),AND(Q$5>=3,Q$5<=5), OR($B7="GS-GRID SX160",$B7="E'GRID T6"),AND(Q$5>=3,Q$5<=6), OR($B7="GS-GRID B30/30XL",$B7="GS-GRID B40/40",$B7="GS-GRID B40/40L"),AND(Q$5>=4,Q$5<=6), OR($B7="GS-GRID SX170",$B7="E'GRID T7"),AND(Q$5>=4,Q$5<=6), $B7="E'GRID T9L",AND(Q$5>=4,Q$5<=6), TRUE,FALSE ),"x","") )}
B8: Tensar HX5.5 | C8: Tensar | D8: Hexagonalt | E8: 0.05 | F8: Ej oplyst | G8: Ej oplyst | H8: 20 | I8: Ej oplyst | J8: Effektindeks 95 | K8: Ej oplyst | L8: {=IF(OR($B8="Anden armering",$B8=""),"",IF(_xlfn.IFS( $B8="Tensar TriAx TX150",AND(L$5>=1,L$5<=4), $B8="Tensar TriAx TX160",AND(L$5>=3,L$5<=6), $B8="Tensar InterAx NX750",AND(L$5>=5,L$5<=6), $B8="Tensar InterAx NX850",AND(L$5>=5,L$5<=6), $B8="Tensar HX5.5",AND(L$5>=1,L$5<=5), $B8="Tensar SS30",AND(L$5>=3,L$5<=5), $B8="Tensar HX165",AND(L$5>=4,L$5<=6), OR($B8="GS-GRID B20/20",$B8="GS-GRID B20/20L"),AND(L$5>=1,L$5<=3), OR($B8="GS-GRID B30/30",$B8="GS-GRID B30/30L"),AND(L$5>=3,L$5<=5), OR($B8="GS-GRID SX160",$B8="E'GRID T6"),AND(L$5>=3,L$5<=6), OR($B8="GS-GRID B30/30XL",$B8="GS-GRID B40/40",$B8="GS-GRID B40/40L"),AND(L$5>=4,L$5<=6), OR($B8="GS-GRID SX170",$B8="E'GRID T7"),AND(L$5>=4,L$5<=6), $B8="E'GRID T9L",AND(L$5>=4,L$5<=6), TRUE,FALSE ),"x","") )} -> x | M8: {=IF(OR($B8="Anden armering",$B8=""),"",IF(_xlfn.IFS( $B8="Tensar TriAx TX150",AND(M$5>=1,M$5<=4), $B8="Tensar TriAx TX160",AND(M$5>=3,M$5<=6), $B8="Tensar InterAx NX750",AND(M$5>=5,M$5<=6), $B8="Tensar InterAx NX850",AND(M$5>=5,M$5<=6), $B8="Tensar HX5.5",AND(M$5>=1,M$5<=5), $B8="Tensar SS30",AND(M$5>=3,M$5<=5), $B8="Tensar HX165",AND(M$5>=4,M$5<=6), OR($B8="GS-GRID B20/20",$B8="GS-GRID B20/20L"),AND(M$5>=1,M$5<=3), OR($B8="GS-GRID B30/30",$B8="GS-GRID B30/30L"),AND(M$5>=3,M$5<=5), OR($B8="GS-GRID SX160",$B8="E'GRID T6"),AND(M$5>=3,M$5<=6), OR($B8="GS-GRID B30/30XL",$B8="GS-GRID B40/40",$B8="GS-GRID B40/40L"),AND(M$5>=4,M$5<=6), OR($B8="GS-GRID SX170",$B8="E'GRID T7"),AND(M$5>=4,M$5<=6), $B8="E'GRID T9L",AND(M$5>=4,M$5<=6), TRUE,FALSE ),"x","") )} -> x | N8: {=IF(OR($B8="Anden armering",$B8=""),"",IF(_xlfn.IFS( $B8="Tensar TriAx TX150",AND(N$5>=1,N$5<=4), $B8="Tensar TriAx TX160",AND(N$5>=3,N$5<=6), $B8="Tensar InterAx NX750",AND(N$5>=5,N$5<=6), $B8="Tensar InterAx NX850",AND(N$5>=5,N$5<=6), $B8="Tensar HX5.5",AND(N$5>=1,N$5<=5), $B8="Tensar SS30",AND(N$5>=3,N$5<=5), $B8="Tensar HX165",AND(N$5>=4,N$5<=6), OR($B8="GS-GRID B20/20",$B8="GS-GRID B20/20L"),AND(N$5>=1,N$5<=3), OR($B8="GS-GRID B30/30",$B8="GS-GRID B30/30L"),AND(N$5>=3,N$5<=5), OR($B8="GS-GRID SX160",$B8="E'GRID T6"),AND(N$5>=3,N$5<=6), OR($B8="GS-GRID B30/30XL",$B8="GS-GRID B40/40",$B8="GS-GRID B40/40L"),AND(N$5>=4,N$5<=6), OR($B8="GS-GRID SX170",$B8="E'GRID T7"),AND(N$5>=4,N$5<=6), $B8="E'GRID T9L",AND(N$5>=4,N$5<=6), TRUE,FALSE ),"x","") )} -> x | O8: {=IF(OR($B8="Anden armering",$B8=""),"",IF(_xlfn.IFS( $B8="Tensar TriAx TX150",AND(O$5>=1,O$5<=4), $B8="Tensar TriAx TX160",AND(O$5>=3,O$5<=6), $B8="Tensar InterAx NX750",AND(O$5>=5,O$5<=6), $B8="Tensar InterAx NX850",AND(O$5>=5,O$5<=6), $B8="Tensar HX5.5",AND(O$5>=1,O$5<=5), $B8="Tensar SS30",AND(O$5>=3,O$5<=5), $B8="Tensar HX165",AND(O$5>=4,O$5<=6), OR($B8="GS-GRID B20/20",$B8="GS-GRID B20/20L"),AND(O$5>=1,O$5<=3), OR($B8="GS-GRID B30/30",$B8="GS-GRID B30/30L"),AND(O$5>=3,O$5<=5), OR($B8="GS-GRID SX160",$B8="E'GRID T6"),AND(O$5>=3,O$5<=6), OR($B8="GS-GRID B30/30XL",$B8="GS-GRID B40/40",$B8="GS-GRID B40/40L"),AND(O$5>=4,O$5<=6), OR($B8="GS-GRID SX170",$B8="E'GRID T7"),AND(O$5>=4,O$5<=6), $B8="E'GRID T9L",AND(O$5>=4,O$5<=6), TRUE,FALSE ),"x","") )} -> x | P8: {=IF(OR($B8="Anden armering",$B8=""),"",IF(_xlfn.IFS( $B8="Tensar TriAx TX150",AND(P$5>=1,P$5<=4), $B8="Tensar TriAx TX160",AND(P$5>=3,P$5<=6), $B8="Tensar InterAx NX750",AND(P$5>=5,P$5<=6), $B8="Tensar InterAx NX850",AND(P$5>=5,P$5<=6), $B8="Tensar HX5.5",AND(P$5>=1,P$5<=5), $B8="Tensar SS30",AND(P$5>=3,P$5<=5), $B8="Tensar HX165",AND(P$5>=4,P$5<=6), OR($B8="GS-GRID B20/20",$B8="GS-GRID B20/20L"),AND(P$5>=1,P$5<=3), OR($B8="GS-GRID B30/30",$B8="GS-GRID B30/30L"),AND(P$5>=3,P$5<=5), OR($B8="GS-GRID SX160",$B8="E'GRID T6"),AND(P$5>=3,P$5<=6), OR($B8="GS-GRID B30/30XL",$B8="GS-GRID B40/40",$B8="GS-GRID B40/40L"),AND(P$5>=4,P$5<=6), OR($B8="GS-GRID SX170",$B8="E'GRID T7"),AND(P$5>=4,P$5<=6), $B8="E'GRID T9L",AND(P$5>=4,P$5<=6), TRUE,FALSE ),"x","") )} -> x | Q8: {=IF(OR($B8="Anden armering",$B8=""),"",IF(_xlfn.IFS( $B8="Tensar TriAx TX150",AND(Q$5>=1,Q$5<=4), $B8="Tensar TriAx TX160",AND(Q$5>=3,Q$5<=6), $B8="Tensar InterAx NX750",AND(Q$5>=5,Q$5<=6), $B8="Tensar InterAx NX850",AND(Q$5>=5,Q$5<=6), $B8="Tensar HX5.5",AND(Q$5>=1,Q$5<=5), $B8="Tensar SS30",AND(Q$5>=3,Q$5<=5), $B8="Tensar HX165",AND(Q$5>=4,Q$5<=6), OR($B8="GS-GRID B20/20",$B8="GS-GRID B20/20L"),AND(Q$5>=1,Q$5<=3), OR($B8="GS-GRID B30/30",$B8="GS-GRID B30/30L"),AND(Q$5>=3,Q$5<=5), OR($B8="GS-GRID SX160",$B8="E'GRID T6"),AND(Q$5>=3,Q$5<=6), OR($B8="GS-GRID B30/30XL",$B8="GS-GRID B40/40",$B8="GS-GRID B40/40L"),AND(Q$5>=4,Q$5<=6), OR($B8="GS-GRID SX170",$B8="E'GRID T7"),AND(Q$5>=4,Q$5<=6), $B8="E'GRID T9L",AND(Q$5>=4,Q$5<=6), TRUE,FALSE ),"x","") )}
B9: Tensar TriAx TX160 | C9: Tensar | D9: Triaxialt | E9: 0 | F9: ribbe 40 mm | G9: 80 | H9: 20 | J9: REFERENCE — effektindeks 100. Max korn udledt fra designmanualens regel: 2 × ribbe 40 mm = 80 mm. | K9: 80 | L9: {=IF(OR($B9="Anden armering",$B9=""),"",IF(_xlfn.IFS( $B9="Tensar TriAx TX150",AND(L$5>=1,L$5<=4), $B9="Tensar TriAx TX160",AND(L$5>=3,L$5<=6), $B9="Tensar InterAx NX750",AND(L$5>=5,L$5<=6), $B9="Tensar InterAx NX850",AND(L$5>=5,L$5<=6), $B9="Tensar HX5.5",AND(L$5>=1,L$5<=5), $B9="Tensar SS30",AND(L$5>=3,L$5<=5), $B9="Tensar HX165",AND(L$5>=4,L$5<=6), OR($B9="GS-GRID B20/20",$B9="GS-GRID B20/20L"),AND(L$5>=1,L$5<=3), OR($B9="GS-GRID B30/30",$B9="GS-GRID B30/30L"),AND(L$5>=3,L$5<=5), OR($B9="GS-GRID SX160",$B9="E'GRID T6"),AND(L$5>=3,L$5<=6), OR($B9="GS-GRID B30/30XL",$B9="GS-GRID B40/40",$B9="GS-GRID B40/40L"),AND(L$5>=4,L$5<=6), OR($B9="GS-GRID SX170",$B9="E'GRID T7"),AND(L$5>=4,L$5<=6), $B9="E'GRID T9L",AND(L$5>=4,L$5<=6), TRUE,FALSE ),"x","") )} | M9: {=IF(OR($B9="Anden armering",$B9=""),"",IF(_xlfn.IFS( $B9="Tensar TriAx TX150",AND(M$5>=1,M$5<=4), $B9="Tensar TriAx TX160",AND(M$5>=3,M$5<=6), $B9="Tensar InterAx NX750",AND(M$5>=5,M$5<=6), $B9="Tensar InterAx NX850",AND(M$5>=5,M$5<=6), $B9="Tensar HX5.5",AND(M$5>=1,M$5<=5), $B9="Tensar SS30",AND(M$5>=3,M$5<=5), $B9="Tensar HX165",AND(M$5>=4,M$5<=6), OR($B9="GS-GRID B20/20",$B9="GS-GRID B20/20L"),AND(M$5>=1,M$5<=3), OR($B9="GS-GRID B30/30",$B9="GS-GRID B30/30L"),AND(M$5>=3,M$5<=5), OR($B9="GS-GRID SX160",$B9="E'GRID T6"),AND(M$5>=3,M$5<=6), OR($B9="GS-GRID B30/30XL",$B9="GS-GRID B40/40",$B9="GS-GRID B40/40L"),AND(M$5>=4,M$5<=6), OR($B9="GS-GRID SX170",$B9="E'GRID T7"),AND(M$5>=4,M$5<=6), $B9="E'GRID T9L",AND(M$5>=4,M$5<=6), TRUE,FALSE ),"x","") )} | N9: {=IF(OR($B9="Anden armering",$B9=""),"",IF(_xlfn.IFS( $B9="Tensar TriAx TX150",AND(N$5>=1,N$5<=4), $B9="Tensar TriAx TX160",AND(N$5>=3,N$5<=6), $B9="Tensar InterAx NX750",AND(N$5>=5,N$5<=6), $B9="Tensar InterAx NX850",AND(N$5>=5,N$5<=6), $B9="Tensar HX5.5",AND(N$5>=1,N$5<=5), $B9="Tensar SS30",AND(N$5>=3,N$5<=5), $B9="Tensar HX165",AND(N$5>=4,N$5<=6), OR($B9="GS-GRID B20/20",$B9="GS-GRID B20/20L"),AND(N$5>=1,N$5<=3), OR($B9="GS-GRID B30/30",$B9="GS-GRID B30/30L"),AND(N$5>=3,N$5<=5), OR($B9="GS-GRID SX160",$B9="E'GRID T6"),AND(N$5>=3,N$5<=6), OR($B9="GS-GRID B30/30XL",$B9="GS-GRID B40/40",$B9="GS-GRID B40/40L"),AND(N$5>=4,N$5<=6), OR($B9="GS-GRID SX170",$B9="E'GRID T7"),AND(N$5>=4,N$5<=6), $B9="E'GRID T9L",AND(N$5>=4,N$5<=6), TRUE,FALSE ),"x","") )} -> x | O9: {=IF(OR($B9="Anden armering",$B9=""),"",IF(_xlfn.IFS( $B9="Tensar TriAx TX150",AND(O$5>=1,O$5<=4), $B9="Tensar TriAx TX160",AND(O$5>=3,O$5<=6), $B9="Tensar InterAx NX750",AND(O$5>=5,O$5<=6), $B9="Tensar InterAx NX850",AND(O$5>=5,O$5<=6), $B9="Tensar HX5.5",AND(O$5>=1,O$5<=5), $B9="Tensar SS30",AND(O$5>=3,O$5<=5), $B9="Tensar HX165",AND(O$5>=4,O$5<=6), OR($B9="GS-GRID B20/20",$B9="GS-GRID B20/20L"),AND(O$5>=1,O$5<=3), OR($B9="GS-GRID B30/30",$B9="GS-GRID B30/30L"),AND(O$5>=3,O$5<=5), OR($B9="GS-GRID SX160",$B9="E'GRID T6"),AND(O$5>=3,O$5<=6), OR($B9="GS-GRID B30/30XL",$B9="GS-GRID B40/40",$B9="GS-GRID B40/40L"),AND(O$5>=4,O$5<=6), OR($B9="GS-GRID SX170",$B9="E'GRID T7"),AND(O$5>=4,O$5<=6), $B9="E'GRID T9L",AND(O$5>=4,O$5<=6), TRUE,FALSE ),"x","") )} -> x | P9: {=IF(OR($B9="Anden armering",$B9=""),"",IF(_xlfn.IFS( $B9="Tensar TriAx TX150",AND(P$5>=1,P$5<=4), $B9="Tensar TriAx TX160",AND(P$5>=3,P$5<=6), $B9="Tensar InterAx NX750",AND(P$5>=5,P$5<=6), $B9="Tensar InterAx NX850",AND(P$5>=5,P$5<=6), $B9="Tensar HX5.5",AND(P$5>=1,P$5<=5), $B9="Tensar SS30",AND(P$5>=3,P$5<=5), $B9="Tensar HX165",AND(P$5>=4,P$5<=6), OR($B9="GS-GRID B20/20",$B9="GS-GRID B20/20L"),AND(P$5>=1,P$5<=3), OR($B9="GS-GRID B30/30",$B9="GS-GRID B30/30L"),AND(P$5>=3,P$5<=5), OR($B9="GS-GRID SX160",$B9="E'GRID T6"),AND(P$5>=3,P$5<=6), OR($B9="GS-GRID B30/30XL",$B9="GS-GRID B40/40",$B9="GS-GRID B40/40L"),AND(P$5>=4,P$5<=6), OR($B9="GS-GRID SX170",$B9="E'GRID T7"),AND(P$5>=4,P$5<=6), $B9="E'GRID T9L",AND(P$5>=4,P$5<=6), TRUE,FALSE ),"x","") )} -> x | Q9: {=IF(OR($B9="Anden armering",$B9=""),"",IF(_xlfn.IFS( $B9="Tensar TriAx TX150",AND(Q$5>=1,Q$5<=4), $B9="Tensar TriAx TX160",AND(Q$5>=3,Q$5<=6), $B9="Tensar InterAx NX750",AND(Q$5>=5,Q$5<=6), $B9="Tensar InterAx NX850",AND(Q$5>=5,Q$5<=6), $B9="Tensar HX5.5",AND(Q$5>=1,Q$5<=5), $B9="Tensar SS30",AND(Q$5>=3,Q$5<=5), $B9="Tensar HX165",AND(Q$5>=4,Q$5<=6), OR($B9="GS-GRID B20/20",$B9="GS-GRID B20/20L"),AND(Q$5>=1,Q$5<=3), OR($B9="GS-GRID B30/30",$B9="GS-GRID B30/30L"),AND(Q$5>=3,Q$5<=5), OR($B9="GS-GRID SX160",$B9="E'GRID T6"),AND(Q$5>=3,Q$5<=6), OR($B9="GS-GRID B30/30XL",$B9="GS-GRID B40/40",$B9="GS-GRID B40/40L"),AND(Q$5>=4,Q$5<=6), OR($B9="GS-GRID SX170",$B9="E'GRID T7"),AND(Q$5>=4,Q$5<=6), $B9="E'GRID T9L",AND(Q$5>=4,Q$5<=6), TRUE,FALSE ),"x","") )} -> x
